Workbook

Sheet Δεδομένα
A1: Εναλλακτικές / Χαρακτηριστικά | B1: Ενοίκιο (Κ) | C1: Εμβαδό (Ο) | D1: Δωμάτια (Ο) | E1: Πάρκινγκ (Ο) | F1: Θέρμανση (Ο) | G1: Απόστ. ΜΜΜ (Κ) | H1: Απόστ. Αγορά (Κ) | I1: Κατάσταση (Ο) | J1: Όροφος (Ο) | K1: Έτος (Ο)
A2: A | B2: 500 | C2: 90 | D2: 3 | E2: 2 | F2: 0 | G2: 500 | H2: 500 | I2: 2 | J2: 4 | K2: 1995
A3: B | B3: 400 | C3: 55 | D3: 2 | E3: 1 | F3: 0 | G3: 2000 | H3: 0 | I3: 2 | J3: 3 | K3: 2015
A4: Γ | B4: 350 | C4: 70 | D4: 3 | E4: 0 | F4: 1 | G4: 200 | H4: 200 | I4: 1 | J4: 2 | K4: 2005
A5: Δ | B5: 700 | C5: 120 | D5: 4 | E5: 3 | F5: 1 | G5: 4000 | H5: 300 | I5: 4 | J5: 1 | K5: 2025
A6: E | B6: 250 | C6: 35 | D6: 1 | E6: 0 | F6: 0 | G6: 0 | H6: 0 | I6: 0 | J6: 0 | K6: 1985
A7: Z | B7: 600 | C7: 100 | D7: 3 | E7: 3 | F7: 1 | G7: 2000 | H7: 1000 | I7: 3 | J7: 3 | K7: 2000
A8: H | B8: 300 | C8: 50 | D8: 2 | E8: 0 | F8: 0 | G8: 100 | H8: 100 | I8: 1 | J8: 1 | K8: 1970

Sheet Κανονικοποίηση
A1: Εναλλακτικές / Χαρακτηριστικά | B1: Ενοίκιο (Κ) | C1: Εμβαδό (Ο) | D1: Δωμάτια (Ο) | E1: Πάρκινγκ (Ο) | F1: Θέρμανση (Ο) | G1: Απόστ. ΜΜΜ (Κ) | H1: Απόστ. Αγορά (Κ) | I1: Κατάσταση (Ο) | J1: Όροφος (Ο) | K1: Έτος (Ο)
A2: A | B2: =IF(Δεδομένα!B2<=400, 1 - (Δεδομένα!B2-250)/(400-250)*(1-0.7), 0.7 - (Δεδομένα!B2-400)/(700-400)*0.7) -> 0.46666667 | C2: =(Δεδομένα!C2 - MIN(Δεδομένα!C$2:C$8)) / (MAX(Δεδομένα!C$2:C$8) - MIN(Δεδομένα!C$2:C$8)) -> 0.64705882 | D2: =(Δεδομένα!D2 - MIN(Δεδομένα!D$2:D$8)) / (MAX(Δεδομένα!D$2:D$8) - MIN(Δεδομένα!D$2:D$8)) -> 0.66666667 | E2: =(Δεδομένα!E2 - MIN(Δεδομένα!E$2:E$8)) / (MAX(Δεδομένα!E$2:E$8) - MIN(Δεδομένα!E$2:E$8)) -> 0.66666667 | F2: =(Δεδομένα!F2 - MIN(Δεδομένα!F$2:F$8)) / (MAX(Δεδομένα!F$2:F$8) - MIN(Δεδομένα!F$2:F$8)) -> 0 | G2: =(MAX(Δεδομένα!G$2:G$8) - Δεδομένα!G2) / (MAX(Δεδομένα!G$2:G$8) - MIN(Δεδομένα!G$2:G$8)) -> 0.875 | H2: =(MAX(Δεδομένα!H$2:H$8) - Δεδομένα!H2) / (MAX(Δεδομένα!H$2:H$8) - MIN(Δεδομένα!H$2:H$8)) -> 0.5 | I2: =(Δεδομένα!I2 - MIN(Δεδομένα!I$2:I$8)) / (MAX(Δεδομένα!I$2:I$8) - MIN(Δεδομένα!I$2:I$8)) -> 0.5 | J2: =(Δεδομένα!J2 - MIN(Δεδομένα!J$2:J$8)) / (MAX(Δεδομένα!J$2:J$8) - MIN(Δεδομένα!J$2:J$8)) -> 1 | K2: =(Δεδομένα!K2 - MIN(Δεδομένα!K$2:K$8)) / (MAX(Δεδομένα!K$2:K$8) - MIN(Δεδομένα!K$2:K$8)) -> 0.45454545
A3: B | B3: =IF(Δεδομένα!B3<=400, 1 - (Δεδομένα!B3-250)/(400-250)*(1-0.7), 0.7 - (Δεδομένα!B3-400)/(700-400)*0.7) -> 0.7 | C3: =(Δεδομένα!C3 - MIN(Δεδομένα!C$2:C$8)) / (MAX(Δεδομένα!C$2:C$8) - MIN(Δεδομένα!C$2:C$8)) -> 0.23529412 | D3: =(Δεδομένα!D3 - MIN(Δεδομένα!D$2:D$8)) / (MAX(Δεδομένα!D$2:D$8) - MIN(Δεδομένα!D$2:D$8)) -> 0.33333333 | E3: =(Δεδομένα!E3 - MIN(Δεδομένα!E$2:E$8)) / (MAX(Δεδομένα!E$2:E$8) - MIN(Δεδομένα!E$2:E$8)) -> 0.33333333 | F3: =(Δεδομένα!F3 - MIN(Δεδομένα!F$2:F$8)) / (MAX(Δεδομένα!F$2:F$8) - MIN(Δεδομένα!F$2:F$8)) -> 0 | G3: =(MAX(Δεδομένα!G$2:G$8) - Δεδομένα!G3) / (MAX(Δεδομένα!G$2:G$8) - MIN(Δεδομένα!G$2:G$8)) -> 0.5 | H3: =(MAX(Δεδομένα!H$2:H$8) - Δεδομένα!H3) / (MAX(Δεδομένα!H$2:H$8) - MIN(Δεδομένα!H$2:H$8)) -> 1 | I3: =(Δεδομένα!I3 - MIN(Δεδομένα!I$2:I$8)) / (MAX(Δεδομένα!I$2:I$8) - MIN(Δεδομένα!I$2:I$8)) -> 0.5 | J3: =(Δεδομένα!J3 - MIN(Δεδομένα!J$2:J$8)) / (MAX(Δεδομένα!J$2:J$8) - MIN(Δεδομένα!J$2:J$8)) -> 0.75 | K3: =(Δεδομένα!K3 - MIN(Δεδομένα!K$2:K$8)) / (MAX(Δεδομένα!K$2:K$8) - MIN(Δεδομένα!K$2:K$8)) -> 0.81818182
A4: Γ | B4: =IF(Δεδομένα!B4<=400, 1 - (Δεδομένα!B4-250)/(400-250)*(1-0.7), 0.7 - (Δεδομένα!B4-400)/(700-400)*0.7) -> 0.8 | C4: =(Δεδομένα!C4 - MIN(Δεδομένα!C$2:C$8)) / (MAX(Δεδομένα!C$2:C$8) - MIN(Δεδομένα!C$2:C$8)) -> 0.41176471 | D4: =(Δεδομένα!D4 - MIN(Δεδομένα!D$2:D$8)) / (MAX(Δεδομένα!D$2:D$8) - MIN(Δεδομένα!D$2:D$8)) -> 0.66666667 | E4: =(Δεδομένα!E4 - MIN(Δεδομένα!E$2:E$8)) / (MAX(Δεδομένα!E$2:E$8) - MIN(Δεδομένα!E$2:E$8)) -> 0 | F4: =(Δεδομένα!F4 - MIN(Δεδομένα!F$2:F$8)) / (MAX(Δεδομένα!F$2:F$8) - MIN(Δεδομένα!F$2:F$8)) -> 1 | G4: =(MAX(Δεδομένα!G$2:G$8) - Δεδομένα!G4) / (MAX(Δεδομένα!G$2:G$8) - MIN(Δεδομένα!G$2:G$8)) -> 0.95 | H4: =(MAX(Δεδομένα!H$2:H$8) - Δεδομένα!H4) / (MAX(Δεδομένα!H$2:H$8) - MIN(Δεδομένα!H$2:H$8)) -> 0.8 | I4: =(Δεδομένα!I4 - MIN(Δεδομένα!I$2:I$8)) / (MAX(Δεδομένα!I$2:I$8) - MIN(Δεδομένα!I$2:I$8)) -> 0.25 | J4: =(Δεδομένα!J4 - MIN(Δεδομένα!J$2:J$8)) / (MAX(Δεδομένα!J$2:J$8) - MIN(Δεδομένα!J$2:J$8)) -> 0.5 | K4: =(Δεδομένα!K4 - MIN(Δεδομένα!K$2:K$8)) / (MAX(Δεδομένα!K$2:K$8) - MIN(Δεδομένα!K$2:K$8)) -> 0.63636364
A5: Δ | B5: =IF(Δεδομένα!B5<=400, 1 - (Δεδομένα!B5-250)/(400-250)*(1-0.7), 0.7 - (Δεδομένα!B5-400)/(700-400)*0.7) -> 0 | C5: =(Δεδομένα!C5 - MIN(Δεδομένα!C$2:C$8)) / (MAX(Δεδομένα!C$2:C$8) - MIN(Δεδομένα!C$2:C$8)) -> 1 | D5: =(Δεδομένα!D5 - MIN(Δεδομένα!D$2:D$8)) / (MAX(Δεδομένα!D$2:D$8) - MIN(Δεδομένα!D$2:D$8)) -> 1 | E5: =(Δεδομένα!E5 - MIN(Δεδομένα!E$2:E$8)) / (MAX(Δεδομένα!E$2:E$8) - MIN(Δεδομένα!E$2:E$8)) -> 1 | F5: =(Δεδομένα!F5 - MIN(Δεδομένα!F$2:F$8)) / (MAX(Δεδομένα!F$2:F$8) - MIN(Δεδομένα!F$2:F$8)) -> 1 | G5: =(MAX(Δεδομένα!G$2:G$8) - Δεδομένα!G5) / (MAX(Δεδομένα!G$2:G$8) - MIN(Δεδομένα!G$2:G$8)) -> 0 | H5: =(MAX(Δεδομένα!H$2:H$8) - Δεδομένα!H5) / (MAX(Δεδομένα!H$2:H$8) - MIN(Δεδομένα!H$2:H$8)) -> 0.7 | I5: =(Δεδομένα!I5 - MIN(Δεδομένα!I$2:I$8)) / (MAX(Δεδομένα!I$2:I$8) - MIN(Δεδομένα!I$2:I$8)) -> 1 | J5: =(Δεδομένα!J5 - MIN(Δεδομένα!J$2:J$8)) / (MAX(Δεδομένα!J$2:J$8) - MIN(Δεδομένα!J$2:J$8)) -> 0.25 | K5: =(Δεδομένα!K5 - MIN(Δεδομένα!K$2:K$8)) / (MAX(Δεδομένα!K$2:K$8) - MIN(Δεδομένα!K$2:K$8)) -> 1
A6: E | B6: =IF(Δεδομένα!B6<=400, 1 - (Δεδομένα!B6-250)/(400-250)*(1-0.7), 0.7 - (Δεδομένα!B6-400)/(700-400)*0.7) -> 1 | C6: =(Δεδομένα!C6 - MIN(Δεδομένα!C$2:C$8)) / (MAX(Δεδομένα!C$2:C$8) - MIN(Δεδομένα!C$2:C$8)) -> 0 | D6: =(Δεδομένα!D6 - MIN(Δεδομένα!D$2:D$8)) / (MAX(Δεδομένα!D$2:D$8) - MIN(Δεδομένα!D$2:D$8)) -> 0 | E6: =(Δεδομένα!E6 - MIN(Δεδομένα!E$2:E$8)) / (MAX(Δεδομένα!E$2:E$8) - MIN(Δεδομένα!E$2:E$8)) -> 0 | F6: =(Δεδομένα!F6 - MIN(Δεδομένα!F$2:F$8)) / (MAX(Δεδομένα!F$2:F$8) - MIN(Δεδομένα!F$2:F$8)) -> 0 | G6: =(MAX(Δεδομένα!G$2:G$8) - Δεδομένα!G6) / (MAX(Δεδομένα!G$2:G$8) - MIN(Δεδομένα!G$2:G$8)) -> 1 | H6: =(MAX(Δεδομένα!H$2:H$8) - Δεδομένα!H6) / (MAX(Δεδομένα!H$2:H$8) - MIN(Δεδομένα!H$2:H$8)) -> 1 | I6: =(Δεδομένα!I6 - MIN(Δεδομένα!I$2:I$8)) / (MAX(Δεδομένα!I$2:I$8) - MIN(Δεδομένα!I$2:I$8)) -> 0 | J6: =(Δεδομένα!J6 - MIN(Δεδομένα!J$2:J$8)) / (MAX(Δεδομένα!J$2:J$8) - MIN(Δεδομένα!J$2:J$8)) -> 0 | K6: =(Δεδομένα!K6 - MIN(Δεδομένα!K$2:K$8)) / (MAX(Δεδομένα!K$2:K$8) - MIN(Δεδομένα!K$2:K$8)) -> 0.27272727
A7: Z | B7: =IF(Δεδομένα!B7<=400, 1 - (Δεδομένα!B7-250)/(400-250)*(1-0.7), 0.7 - (Δεδομένα!B7-400)/(700-400)*0.7) -> 0.23333333 | C7: =(Δεδομένα!C7 - MIN(Δεδομένα!C$2:C$8)) / (MAX(Δεδομένα!C$2:C$8) - MIN(Δεδομένα!C$2:C$8)) -> 0.76470588 | D7: =(Δεδομένα!D7 - MIN(Δεδομένα!D$2:D$8)) / (MAX(Δεδομένα!D$2:D$8) - MIN(Δεδομένα!D$2:D$8)) -> 0.66666667 | E7: =(Δεδομένα!E7 - MIN(Δεδομένα!E$2:E$8)) / (MAX(Δεδομένα!E$2:E$8) - MIN(Δεδομένα!E$2:E$8)) -> 1 | F7: =(Δεδομένα!F7 - MIN(Δεδομένα!F$2:F$8)) / (MAX(Δεδομένα!F$2:F$8) - MIN(Δεδομένα!F$2:F$8)) -> 1 | G7: =(MAX(Δεδομένα!G$2:G$8) - Δεδομένα!G7) / (MAX(Δεδομένα!G$2:G$8) - MIN(Δεδομένα!G$2:G$8)) -> 0.5 | H7: =(MAX(Δεδομένα!H$2:H$8) - Δεδομένα!H7) / (MAX(Δεδομένα!H$2:H$8) - MIN(Δεδομένα!H$2:H$8)) -> 0 | I7: =(Δεδομένα!I7 - MIN(Δεδομένα!I$2:I$8)) / (MAX(Δεδομένα!I$2:I$8) - MIN(Δεδομένα!I$2:I$8)) -> 0.75 | J7: =(Δεδομένα!J7 - MIN(Δεδομένα!J$2:J$8)) / (MAX(Δεδομένα!J$2:J$8) - MIN(Δεδομένα!J$2:J$8)) -> 0.75 | K7: =(Δεδομένα!K7 - MIN(Δεδομένα!K$2:K$8)) / (MAX(Δεδομένα!K$2:K$8) - MIN(Δεδομένα!K$2:K$8)) -> 0.54545455
A8: H | B8: =IF(Δεδομένα!B8<=400, 1 - (Δεδομένα!B8-250)/(400-250)*(1-0.7), 0.7 - (Δεδομένα!B8-400)/(700-400)*0.7) -> 0.9 | C8: =(Δεδομένα!C8 - MIN(Δεδομένα!C$2:C$8)) / (MAX(Δεδομένα!C$2:C$8) - MIN(Δεδομένα!C$2:C$8)) -> 0.17647059 | D8: =(Δεδομένα!D8 - MIN(Δεδομένα!D$2:D$8)) / (MAX(Δεδομένα!D$2:D$8) - MIN(Δεδομένα!D$2:D$8)) -> 0.33333333 | E8: =(Δεδομένα!E8 - MIN(Δεδομένα!E$2:E$8)) / (MAX(Δεδομένα!E$2:E$8) - MIN(Δεδομένα!E$2:E$8)) -> 0 | F8: =(Δεδομένα!F8 - MIN(Δεδομένα!F$2:F$8)) / (MAX(Δεδομένα!F$2:F$8) - MIN(Δεδομένα!F$2:F$8)) -> 0 | G8: =(MAX(Δεδομένα!G$2:G$8) - Δεδομένα!G8) / (MAX(Δεδομένα!G$2:G$8) - MIN(Δεδομένα!G$2:G$8)) -> 0.975 | H8: =(MAX(Δεδομένα!H$2:H$8) - Δεδομένα!H8) / (MAX(Δεδομένα!H$2:H$8) - MIN(Δεδομένα!H$2:H$8)) -> 0.9 | I8: =(Δεδομένα!I8 - MIN(Δεδομένα!I$2:I$8)) / (MAX(Δεδομένα!I$2:I$8) - MIN(Δεδομένα!I$2:I$8)) -> 0.25 | J8: =(Δεδομένα!J8 - MIN(Δεδομένα!J$2:J$8)) / (MAX(Δεδομένα!J$2:J$8) - MIN(Δεδομένα!J$2:J$8)) -> 0.25 | K8: =(Δεδομένα!K8 - MIN(Δεδομένα!K$2:K$8)) / (MAX(Δεδομένα!K$2:K$8) - MIN(Δεδομένα!K$2:K$8)) -> 0

Sheet Σταθμισμένο Άθροισμα
A1: Εναλλακτικές / Μέθοδοι Βαρών | B1: Σταθμισμένο Άθροισμα (ROC) | C1: Σταθμισμένο Άθροισμα (Rank Sum) | D1: Σταθμισμένο Άθροισμα (Rank Reciprocal) | E1: Σταθμισμένο Άθροισμα (SMART)
A2: A | B2: {=SUMPRODUCT(Κανονικοποίηση!$B2:$K2, TRANSPOSE(Βάρη!$E$2:$E$11))} -> 0.56319522 | C2: {=SUMPRODUCT(Κανονικοποίηση!$B2:$K2, TRANSPOSE(Βάρη!$C$2:$C$11))} -> 0.5739953 | D2: {=SUMPRODUCT(Κανονικοποίηση!$B2:$K2, TRANSPOSE(Βάρη!$D$2:$D$11))} -> 0.56179238 | E2: {=SUMPRODUCT(Κανονικοποίηση!$B2:$K2, TRANSPOSE(Βάρη!$F$2:$F$11))} -> 0.56035894
A3: B | B3: {=SUMPRODUCT(Κανονικοποίηση!$B3:$K3, TRANSPOSE(Βάρη!$E$2:$E$11))} -> 0.46940687 | C3: {=SUMPRODUCT(Κανονικοποίηση!$B3:$K3, TRANSPOSE(Βάρη!$C$2:$C$11))} -> 0.45337871 | D3: {=SUMPRODUCT(Κανονικοποίηση!$B3:$K3, TRANSPOSE(Βάρη!$D$2:$D$11))} -> 0.50923349 | E3: {=SUMPRODUCT(Κανονικοποίηση!$B3:$K3, TRANSPOSE(Βάρη!$F$2:$F$11))} -> 0.4442878
A4: Γ | B4: {=SUMPRODUCT(Κανονικοποίηση!$B4:$K4, TRANSPOSE(Βάρη!$E$2:$E$11))} -> 0.64414335 | C4: {=SUMPRODUCT(Κανονικοποίηση!$B4:$K4, TRANSPOSE(Βάρη!$C$2:$C$11))} -> 0.62228326 | D4: {=SUMPRODUCT(Κανονικοποίηση!$B4:$K4, TRANSPOSE(Βάρη!$D$2:$D$11))} -> 0.64919214 | E4: {=SUMPRODUCT(Κανονικοποίηση!$B4:$K4, TRANSPOSE(Βάρη!$F$2:$F$11))} -> 0.60682871
A5: Δ | B5: {=SUMPRODUCT(Κανονικοποίηση!$B5:$K5, TRANSPOSE(Βάρη!$E$2:$E$11))} -> 0.579995 | C5: {=SUMPRODUCT(Κανονικοποίηση!$B5:$K5, TRANSPOSE(Βάρη!$C$2:$C$11))} -> 0.64727273 | D5: {=SUMPRODUCT(Κανονικοποίηση!$B5:$K5, TRANSPOSE(Βάρη!$D$2:$D$11))} -> 0.53197399 | E5: {=SUMPRODUCT(Κανονικοποίηση!$B5:$K5, TRANSPOSE(Βάρη!$F$2:$F$11))} -> 0.67818182
A6: E | B6: {=SUMPRODUCT(Κανονικοποίηση!$B6:$K6, TRANSPOSE(Βάρη!$E$2:$E$11))} -> 0.44185455 | C6: {=SUMPRODUCT(Κανονικοποίηση!$B6:$K6, TRANSPOSE(Βάρη!$C$2:$C$11))} -> 0.36859504 | D6: {=SUMPRODUCT(Κανονικοποίηση!$B6:$K6, TRANSPOSE(Βάρη!$D$2:$D$11))} -> 0.47875996 | E6: {=SUMPRODUCT(Κανονικοποίηση!$B6:$K6, TRANSPOSE(Βάρη!$F$2:$F$11))} -> 0.35041322
A7: Z | B7: {=SUMPRODUCT(Κανονικοποίηση!$B7:$K7, TRANSPOSE(Βάρη!$E$2:$E$11))} -> 0.56080586 | C7: {=SUMPRODUCT(Κανονικοποίηση!$B7:$K7, TRANSPOSE(Βάρη!$C$2:$C$11))} -> 0.61080862 | D7: {=SUMPRODUCT(Κανονικοποίηση!$B7:$K7, TRANSPOSE(Βάρη!$D$2:$D$11))} -> 0.53271697 | E7: {=SUMPRODUCT(Κανονικοποίηση!$B7:$K7, TRANSPOSE(Βάρη!$F$2:$F$11))} -> 0.62444498
A8: H | B8: {=SUMPRODUCT(Κανονικοποίηση!$B8:$K8, TRANSPOSE(Βάρη!$E$2:$E$11))} -> 0.50600951 | C8: {=SUMPRODUCT(Κανονικοποίηση!$B8:$K8, TRANSPOSE(Βάρη!$C$2:$C$11))} -> 0.45054367 | D8: {=SUMPRODUCT(Κανονικοποίηση!$B8:$K8, TRANSPOSE(Βάρη!$D$2:$D$11))} -> 0.52352025 | E8: {=SUMPRODUCT(Κανονικοποίηση!$B8:$K8, TRANSPOSE(Βάρη!$F$2:$F$11))} -> 0.4178164

Sheet Σύγκριση & Αποτελέσματα
A1: Εναλλακτικές | B1: Ci​ (ROC) | C1: Ci​ (RS) | D1: Ci​ (RR) | E1: Ci​ (SMART) | F1: Τελική Κατάταξη
A2: A | B2: {=TOPSIS!N13:N19} -> 0.57989445 | C2: {=TOPSIS!N25:N31} -> 0.5948437 | D2: {=TOPSIS!N37:N43} -> 0.55042236 | E2: {=TOPSIS!N49:N55} -> 0.55636757 | F2: =_xlfn.RANK.EQ(B2, $B$2:$B$8, 0) -> 2
A3: B | B3: 0.48180175 | C3: 0.46377531 | D3: 0.52641899 | E3: 0.45365011 | F3: =_xlfn.RANK.EQ(B3, $B$2:$B$8, 0) -> 5
A4: Γ | B4: 0.64121119 | C4: 0.61537352 | D4: 0.6525923 | E4: 0.5683486 | F4: =_xlfn.RANK.EQ(B4, $B$2:$B$8, 0) -> 1
A5: Δ | B5: 0.47315757 | C5: 0.52782911 | D5: 0.43101674 | E5: 0.58990113 | F5: =_xlfn.RANK.EQ(B5, $B$2:$B$8, 0) -> 6
A6: E | B6: 0.53430068 | C6: 0.48839442 | D6: 0.57509938 | E6: 0.450547 | F6: =_xlfn.RANK.EQ(B6, $B$2:$B$8, 0) -> 4
A7: Z | B7: 0.46101089 | C7: 0.48665502 | D7: 0.42744856 | E7: 0.56319271 | F7: =_xlfn.RANK.EQ(B7, $B$2:$B$8, 0) -> 7
A8: H | B8: 0.57226495 | C8: 0.52906326 | D8: 0.60268935 | E8: 0.4673165 | F8: =_xlfn.RANK.EQ(B8, $B$2:$B$8, 0) -> 3

Sheet Βάρη
A1: Κριτήριο | B1: Rank (ri​) | C1: Rank Sum (RS) | D1: Rank Reciprocal (RR) | E1: ROC | F1: SMART (Παράδειγμα)
A2: Ενοίκιο | B2: 1 | C2: =(10 - B2 + 1) / (10 * (10 + 1) / 2) -> 0.18181818 | D2: =(1 / B2) / (1/1 + 1/2 + 1/3 + 1/4 + 1/5 + 1/6 + 1/7 + 1/8 + 1/9 + 1/10) -> 0.34141715 | E2: 0.2929 | F2: =G2 / SUM(G$2:G$11) -> 0.18181818 | G2: 100
A3: Εμβαδό | B3: 2 | C3: =(10 - B3 + 1) / (10 * (10 + 1) / 2) -> 0.16363636 | D3: =(1 / B3) / (1/1 + 1/2 + 1/3 + 1/4 + 1/5 + 1/6 + 1/7 + 1/8 + 1/9 + 1/10) -> 0.17070858 | E3: 0.1929 | F3: =G3 / SUM(G$2:G$11) -> 0.16363636 | G3: 90
A4: Δωμάτια | B4: 3 | C4: =(10 - B4 + 1) / (10 * (10 + 1) / 2) -> 0.14545455 | D4: =(1 / B4) / (1/1 + 1/2 + 1/3 + 1/4 + 1/5 + 1/6 + 1/7 + 1/8 + 1/9 + 1/10) -> 0.11380572 | E4: 0.1429 | F4: =G4 / SUM(G$2:G$11) -> 0.14545455 | G4: 80
A5: Πάρκινγκ | B5: 7 | C5: =(10 - B5 + 1) / (10 * (10 + 1) / 2) -> 0.072727273 | D5: =(1 / B5) / (1/1 + 1/2 + 1/3 + 1/4 + 1/5 + 1/6 + 1/7 + 1/8 + 1/9 + 1/10) -> 0.048773879 | E5: 0.0479 | F5: =G5 / SUM(G$2:G$11) -> 0.12727273 | G5: 70
A6: Θέρμανση | B6: 6 | C6: =(10 - B6 + 1) / (10 * (10 + 1) / 2) -> 0.090909091 | D6: =(1 / B6) / (1/1 + 1/2 + 1/3 + 1/4 + 1/5 + 1/6 + 1/7 + 1/8 + 1/9 + 1/10) -> 0.056902859 | E6: 0.0646 | F6: =G6 / SUM(G$2:G$11) -> 0.10909091 | G6: 60
A7: Απόστ. ΜΜΜ | B7: 4 | C7: =(10 - B7 + 1) / (10 * (10 + 1) / 2) -> 0.12727273 | D7: =(1 / B7) / (1/1 + 1/2 + 1/3 + 1/4 + 1/5 + 1/6 + 1/7 + 1/8 + 1/9 + 1/10) -> 0.085354288 | E7: 0.1096 | F7: =G7 / SUM(G$2:G$11) -> 0.090909091 | G7: 50
A8: Απόστ. Αγορά | B8: 8 | C8: =(10 - B8 + 1) / (10 * (10 + 1) / 2) -> 0.054545455 | D8: =(1 / B8) / (1/1 + 1/2 + 1/3 + 1/4 + 1/5 + 1/6 + 1/7 + 1/8 + 1/9 + 1/10) -> 0.042677144 | E8: 0.0336 | F8: =G8 / SUM(G$2:G$11) -> 0.072727273 | G8: 40
A9: Κατάσταση | B9: 5 | C9: =(10 - B9 + 1) / (10 * (10 + 1) / 2) -> 0.10909091 | D9: =(1 / B9) / (1/1 + 1/2 + 1/3 + 1/4 + 1/5 + 1/6 + 1/7 + 1/8 + 1/9 + 1/10) -> 0.06828343 | E9: 0.0846 | F9: =G9 / SUM(G$2:G$11) -> 0.054545455 | G9: 30
A10: Όροφος | B10: 9 | C10: =(10 - B10 + 1) / (10 * (10 + 1) / 2) -> 0.036363636 | D10: =(1 / B10) / (1/1 + 1/2 + 1/3 + 1/4 + 1/5 + 1/6 + 1/7 + 1/8 + 1/9 + 1/10) -> 0.037935239 | E10: 0.0099 | F10: =G10 / SUM(G$2:G$11) -> 0.036363636 | G10: 20
A11: Έτος | B11: 10 | C11: =(10 - B11 + 1) / (10 * (10 + 1) / 2) -> 0.018181818 | D11: =(1 / B11) / (1/1 + 1/2 + 1/3 + 1/4 + 1/5 + 1/6 + 1/7 + 1/8 + 1/9 + 1/10) -> 0.034141715 | E11: 0.0211 | F11: =G11 / SUM(G$2:G$11) -> 0.018181818 | G11: 10
A12: ΣΥΝΟΛΟ | C12: =SUM(C2:C16) -> 1 | D12: =SUM(D2:D16) -> 1 | E12: =SUM(E2:E16) -> 1 | F12: =SUM(F2:F16) -> 1

Sheet Σύνοψη
L1: PROMETHEE | M1: PROMETHEE | N1: PROMETHEE | O1: PROMETHEE | P1: PROMETHEE | Q1: ELECTRE | R1: ELECTRE | S1: ELECTRE | T1: ELECTRE | U1: ELECTRE
A2: Εναλλακτικές / Μέθοδοι Βαρών | B2: WS-ROC | C2: WS-RS | D2: WS-RR | E2: WS-SMART | F2: TOPSIS-ROC | G2: TOPSIS-RS | H2: TOPSIS-RR | I2: TOPSIS-SMART | J2: AHP | K2: AHP FULL | L2: RANK-ROC | M2: RANK-RS | N2: RANK-SMART | O2: RANK-RR | P2: RANK-AHP | Q2: RANK-ROC | R2: RANK-RS | S2: RANK-RR | T2: RANK-SMART | U2: RANK-AHP
A3: A | B3: ='Σταθμισμένο Άθροισμα'!B2 -> 0.56319522 | C3: ='Σταθμισμένο Άθροισμα'!C2 -> 0.5739953 | D3: ='Σταθμισμένο Άθροισμα'!D2 -> 0.56179238 | E3: ='Σταθμισμένο Άθροισμα'!E2 -> 0.56035894 | F3: {=TOPSIS!N13:N19} -> 0.57989445 | G3: {=TOPSIS!N25:N31} -> 0.5948437 | H3: {=TOPSIS!N37:N43} -> 0.55042236 | I3: {=TOPSIS!N49:N55} -> 0.55636757 | J3: =Κανονικοποίηση!B2*AHP!$L$17 + Κανονικοποίηση!C2*AHP!$L$18 + Κανονικοποίηση!D2*AHP!$L$19 + Κανονικοποίηση!E2*AHP!$L$20 + Κανονικοποίηση!F2*AHP!$L$21 + Κανονικοποίηση!G2*AHP!$L$22 + Κανονικοποίηση!H2*AHP!$L$23 + Κανονικοποίηση!I2*AHP!$L$24 + Κανονικοποίηση!J2*AHP!$L$25 + Κανονικοποίηση!K2*AHP!$L$26 -> 0.55947472 | K3: =AHP!B247 -> 0.079641443 | L3: =PROMETHEE!E61 -> 4 | M3: =PROMETHEE!E71 -> 4 | N3: =PROMETHEE!K61 -> 4 | O3: =PROMETHEE!E81 -> 3 | P3: =PROMETHEE!K71 -> 4 | Q3: =ELECTRE!E62 -> 3 | R3: =ELECTRE!E72 -> 3 | S3: =ELECTRE!E82 -> 3 | T3: =ELECTRE!K62 -> 3 | U3: =ELECTRE!K72 -> 3
A4: B | B4: ='Σταθμισμένο Άθροισμα'!B3 -> 0.46940687 | C4: ='Σταθμισμένο Άθροισμα'!C3 -> 0.45337871 | D4: ='Σταθμισμένο Άθροισμα'!D3 -> 0.50923349 | E4: ='Σταθμισμένο Άθροισμα'!E3 -> 0.4442878 | F4: 0.48180175 | G4: 0.46377531 | H4: 0.52641899 | I4: 0.45365011 | J4: =Κανονικοποίηση!B3*AHP!$L$17 + Κανονικοποίηση!C3*AHP!$L$18 + Κανονικοποίηση!D3*AHP!$L$19 + Κανονικοποίηση!E3*AHP!$L$20 + Κανονικοποίηση!F3*AHP!$L$21 + Κανονικοποίηση!G3*AHP!$L$22 + Κανονικοποίηση!H3*AHP!$L$23 + Κανονικοποίηση!I3*AHP!$L$24 + Κανονικοποίηση!J3*AHP!$L$25 + Κανονικοποίηση!K3*AHP!$L$26 -> 0.45132051 | K4: =AHP!B248 -> 0.062319016 | L4: =PROMETHEE!E62 -> 6 | M4: =PROMETHEE!E72 -> 5 | N4: =PROMETHEE!K62 -> 5 | O4: =PROMETHEE!E82 -> 5 | P4: =PROMETHEE!K72 -> 6 | Q4: =ELECTRE!E63 -> 4 | R4: =ELECTRE!E73 -> 5 | S4: =ELECTRE!E83 -> 4 | T4: =ELECTRE!K63 -> 5 | U4: =ELECTRE!K73 -> 5
A5: Γ | B5: ='Σταθμισμένο Άθροισμα'!B4 -> 0.64414335 | C5: ='Σταθμισμένο Άθροισμα'!C4 -> 0.62228326 | D5: ='Σταθμισμένο Άθροισμα'!D4 -> 0.64919214 | E5: ='Σταθμισμένο Άθροισμα'!E4 -> 0.60682871 | F5: 0.64121119 | G5: 0.61537352 | H5: 0.6525923 | I5: 0.5683486 | J5: =Κανονικοποίηση!B4*AHP!$L$17 + Κανονικοποίηση!C4*AHP!$L$18 + Κανονικοποίηση!D4*AHP!$L$19 + Κανονικοποίηση!E4*AHP!$L$20 + Κανονικοποίηση!F4*AHP!$L$21 + Κανονικοποίηση!G4*AHP!$L$22 + Κανονικοποίηση!H4*AHP!$L$23 + Κανονικοποίηση!I4*AHP!$L$24 + Κανονικοποίηση!J4*AHP!$L$25 + Κανονικοποίηση!K4*AHP!$L$26 -> 0.60103112 | K5: =AHP!B249 -> 0.06434612 | L5: =PROMETHEE!E63 -> 1 | M5: =PROMETHEE!E73 -> 2 | N5: =PROMETHEE!K63 -> 3 | O5: =PROMETHEE!E83 -> 1 | P5: =PROMETHEE!K73 -> 2 | Q5: =ELECTRE!E64 -> 5 | R5: =ELECTRE!E74 -> 4 | S5: =ELECTRE!E84 -> 5 | T5: =ELECTRE!K64 -> 4 | U5: =ELECTRE!K74 -> 4
A6: Δ | B6: ='Σταθμισμένο Άθροισμα'!B5 -> 0.579995 | C6: ='Σταθμισμένο Άθροισμα'!C5 -> 0.64727273 | D6: ='Σταθμισμένο Άθροισμα'!D5 -> 0.53197399 | E6: ='Σταθμισμένο Άθροισμα'!E5 -> 0.67818182 | F6: 0.47315757 | G6: 0.52782911 | H6: 0.43101674 | I6: 0.58990113 | J6: =Κανονικοποίηση!B5*AHP!$L$17 + Κανονικοποίηση!C5*AHP!$L$18 + Κανονικοποίηση!D5*AHP!$L$19 + Κανονικοποίηση!E5*AHP!$L$20 + Κανονικοποίηση!F5*AHP!$L$21 + Κανονικοποίηση!G5*AHP!$L$22 + Κανονικοποίηση!H5*AHP!$L$23 + Κανονικοποίηση!I5*AHP!$L$24 + Κανονικοποίηση!J5*AHP!$L$25 + Κανονικοποίηση!K5*AHP!$L$26 -> 0.64319125 | K6: =AHP!B250 -> 0.28521233 | L6: =PROMETHEE!E64 -> 2 | M6: =PROMETHEE!E74 -> 1 | N6: =PROMETHEE!K64 -> 1 | O6: =PROMETHEE!E84 -> 2 | P6: =PROMETHEE!K74 -> 1 | Q6: =ELECTRE!E65 -> 1 | R6: =ELECTRE!E75 -> 1 | S6: =ELECTRE!E85 -> 1 | T6: =ELECTRE!K65 -> 1 | U6: =ELECTRE!K75 -> 1
A7: E | B7: ='Σταθμισμένο Άθροισμα'!B6 -> 0.44185455 | C7: ='Σταθμισμένο Άθροισμα'!C6 -> 0.36859504 | D7: ='Σταθμισμένο Άθροισμα'!D6 -> 0.47875996 | E7: ='Σταθμισμένο Άθροισμα'!E6 -> 0.35041322 | F7: 0.53430068 | G7: 0.48839442 | H7: 0.57509938 | I7: 0.450547 | J7: =Κανονικοποίηση!B6*AHP!$L$17 + Κανονικοποίηση!C6*AHP!$L$18 + Κανονικοποίηση!D6*AHP!$L$19 + Κανονικοποίηση!E6*AHP!$L$20 + Κανονικοποίηση!F6*AHP!$L$21 + Κανονικοποίηση!G6*AHP!$L$22 + Κανονικοποίηση!H6*AHP!$L$23 + Κανονικοποίηση!I6*AHP!$L$24 + Κανονικοποίηση!J6*AHP!$L$25 + Κανονικοποίηση!K6*AHP!$L$26 -> 0.36883841 | K7: =AHP!B251 -> 0.31710709 | L7: =PROMETHEE!E65 -> 7 | M7: =PROMETHEE!E75 -> 7 | N7: =PROMETHEE!K65 -> 7 | O7: =PROMETHEE!E85 -> 7 | P7: =PROMETHEE!K75 -> 7 | Q7: =ELECTRE!E66 -> 7 | R7: =ELECTRE!E76 -> 7 | S7: =ELECTRE!E86 -> 7 | T7: =ELECTRE!K66 -> 7 | U7: =ELECTRE!K76 -> 7
A8: Z | B8: ='Σταθμισμένο Άθροισμα'!B7 -> 0.56080586 | C8: ='Σταθμισμένο Άθροισμα'!C7 -> 0.61080862 | D8: ='Σταθμισμένο Άθροισμα'!D7 -> 0.53271697 | E8: ='Σταθμισμένο Άθροισμα'!E7 -> 0.62444498 | F8: 0.46101089 | G8: 0.48665502 | H8: 0.42744856 | I8: 0.56319271 | J8: =Κανονικοποίηση!B7*AHP!$L$17 + Κανονικοποίηση!C7*AHP!$L$18 + Κανονικοποίηση!D7*AHP!$L$19 + Κανονικοποίηση!E7*AHP!$L$20 + Κανονικοποίηση!F7*AHP!$L$21 + Κανονικοποίηση!G7*AHP!$L$22 + Κανονικοποίηση!H7*AHP!$L$23 + Κανονικοποίηση!I7*AHP!$L$24 + Κανονικοποίηση!J7*AHP!$L$25 + Κανονικοποίηση!K7*AHP!$L$26 -> 0.6077983 | K8: =AHP!B252 -> 0.11421032 | L8: =PROMETHEE!E66 -> 3 | M8: =PROMETHEE!E76 -> 3 | N8: =PROMETHEE!K66 -> 2 | O8: =PROMETHEE!E86 -> 4 | P8: =PROMETHEE!K76 -> 3 | Q8: =ELECTRE!E67 -> 2 | R8: =ELECTRE!E77 -> 2 | S8: =ELECTRE!E87 -> 2 | T8: =ELECTRE!K67 -> 2 | U8: =ELECTRE!K77 -> 2
A9: H | B9: ='Σταθμισμένο Άθροισμα'!B8 -> 0.50600951 | C9: ='Σταθμισμένο Άθροισμα'!C8 -> 0.45054367 | D9: ='Σταθμισμένο Άθροισμα'!D8 -> 0.52352025 | E9: ='Σταθμισμένο Άθροισμα'!E8 -> 0.4178164 | F9: 0.57226495 | G9: 0.52906326 | H9: 0.60268935 | I9: 0.4673165 | J9: =Κανονικοποίηση!B8*AHP!$L$17 + Κανονικοποίηση!C8*AHP!$L$18 + Κανονικοποίηση!D8*AHP!$L$19 + Κανονικοποίηση!E8*AHP!$L$20 + Κανονικοποίηση!F8*AHP!$L$21 + Κανονικοποίηση!G8*AHP!$L$22 + Κανονικοποίηση!H8*AHP!$L$23 + Κανονικοποίηση!I8*AHP!$L$24 + Κανονικοποίηση!J8*AHP!$L$25 + Κανονικοποίηση!K8*AHP!$L$26 -> 0.42859217 | K9: =AHP!B253 -> 0.077163682 | L9: =PROMETHEE!E67 -> 5 | M9: =PROMETHEE!E77 -> 6 | N9: =PROMETHEE!K67 -> 6 | O9: =PROMETHEE!E87 -> 6 | P9: =PROMETHEE!K77 -> 5 | Q9: =ELECTRE!E68 -> 6 | R9: =ELECTRE!E78 -> 6 | S9: =ELECTRE!E88 -> 6 | T9: =ELECTRE!K68 -> 6 | U9: =ELECTRE!K78 -> 6

Sheet TOPSIS
A1: Πίνακας Κανονικοποίησης l^2
A2: Εναλλακτικές / Χαρακτηριστικά | B2: Ενοίκιο (Κ) | C2: Εμβαδό (Ο) | D2: Δωμάτια (Ο) | E2: Πάρκινγκ (Ο) | F2: Θέρμανση (Ο) | G2: Απόστ. ΜΜΜ (Κ) | H2: Απόστ. Αγορά (Κ) | I2: Κατάσταση (Ο) | J2: Όροφος (Ο) | K2: Έτος (Ο)
A3: A | B3: =Δεδομένα!B2 / SQRT(SUMSQ(Δεδομένα!B$2:B$8)) -> 0.40356716 | C3: =Δεδομένα!C2 / SQRT(SUMSQ(Δεδομένα!C$2:C$8)) -> 0.42832868 | D3: =Δεδομένα!D2 / SQRT(SUMSQ(Δεδομένα!D$2:D$8)) -> 0.41602515 | E3: =Δεδομένα!E2 / SQRT(SUMSQ(Δεδομένα!E$2:E$8)) -> 0.41702883 | F3: =Δεδομένα!F2 / SQRT(SUMSQ(Δεδομένα!F$2:F$8)) -> 0 | G3: =Δεδομένα!G2 / SQRT(SUMSQ(Δεδομένα!G$2:G$8)) -> 0.1014301 | H3: =Δεδομένα!H2 / SQRT(SUMSQ(Δεδομένα!H$2:H$8)) -> 0.42409446 | I3: =Δεδομένα!I2 / SQRT(SUMSQ(Δεδομένα!I$2:I$8)) -> 0.3380617 | ... K3: =Δεδομένα!K2 / SQRT(SUMSQ(Δεδομένα!K$2:K$8)) -> 0.37714064
A4: B | B4: =Δεδομένα!B3 / SQRT(SUMSQ(Δεδομένα!B$2:B$8)) -> 0.32285372 | C4: =Δεδομένα!C3 / SQRT(SUMSQ(Δεδομένα!C$2:C$8)) -> 0.26175642 | D4: =Δεδομένα!D3 / SQRT(SUMSQ(Δεδομένα!D$2:D$8)) -> 0.2773501 | E4: =Δεδομένα!E3 / SQRT(SUMSQ(Δεδομένα!E$2:E$8)) -> 0.20851441 | F4: =Δεδομένα!F3 / SQRT(SUMSQ(Δεδομένα!F$2:F$8)) -> 0 | G4: =Δεδομένα!G3 / SQRT(SUMSQ(Δεδομένα!G$2:G$8)) -> 0.40572041 | H4: =Δεδομένα!H3 / SQRT(SUMSQ(Δεδομένα!H$2:H$8)) -> 0 | I4: =Δεδομένα!I3 / SQRT(SUMSQ(Δεδομένα!I$2:I$8)) -> 0.3380617 | ... K4: =Δεδομένα!K3 / SQRT(SUMSQ(Δεδομένα!K$2:K$8)) -> 0.3809215
A5: Γ | B5: =Δεδομένα!B4 / SQRT(SUMSQ(Δεδομένα!B$2:B$8)) -> 0.28249701 | C5: =Δεδομένα!C4 / SQRT(SUMSQ(Δεδομένα!C$2:C$8)) -> 0.33314453 | D5: =Δεδομένα!D4 / SQRT(SUMSQ(Δεδομένα!D$2:D$8)) -> 0.41602515 | E5: =Δεδομένα!E4 / SQRT(SUMSQ(Δεδομένα!E$2:E$8)) -> 0 | F5: =Δεδομένα!F4 / SQRT(SUMSQ(Δεδομένα!F$2:F$8)) -> 0.57735027 | G5: =Δεδομένα!G4 / SQRT(SUMSQ(Δεδομένα!G$2:G$8)) -> 0.040572041 | H5: =Δεδομένα!H4 / SQRT(SUMSQ(Δεδομένα!H$2:H$8)) -> 0.16963779 | I5: =Δεδομένα!I4 / SQRT(SUMSQ(Δεδομένα!I$2:I$8)) -> 0.16903085 | ... K5: =Δεδομένα!K4 / SQRT(SUMSQ(Δεδομένα!K$2:K$8)) -> 0.37903107
A6: Δ | B6: =Δεδομένα!B5 / SQRT(SUMSQ(Δεδομένα!B$2:B$8)) -> 0.56499402 | C6: =Δεδομένα!C5 / SQRT(SUMSQ(Δεδομένα!C$2:C$8)) -> 0.57110491 | D6: =Δεδομένα!D5 / SQRT(SUMSQ(Δεδομένα!D$2:D$8)) -> 0.5547002 | E6: =Δεδομένα!E5 / SQRT(SUMSQ(Δεδομένα!E$2:E$8)) -> 0.62554324 | F6: =Δεδομένα!F5 / SQRT(SUMSQ(Δεδομένα!F$2:F$8)) -> 0.57735027 | G6: =Δεδομένα!G5 / SQRT(SUMSQ(Δεδομένα!G$2:G$8)) -> 0.81144083 | H6: =Δεδομένα!H5 / SQRT(SUMSQ(Δεδομένα!H$2:H$8)) -> 0.25445668 | I6: =Δεδομένα!I5 / SQRT(SUMSQ(Δεδομένα!I$2:I$8)) -> 0.6761234 | ... K6: =Δεδομένα!K5 / SQRT(SUMSQ(Δεδομένα!K$2:K$8)) -> 0.38281192
A7: E | B7: =Δεδομένα!B6 / SQRT(SUMSQ(Δεδομένα!B$2:B$8)) -> 0.20178358 | C7: =Δεδομένα!C6 / SQRT(SUMSQ(Δεδομένα!C$2:C$8)) -> 0.16657226 | D7: =Δεδομένα!D6 / SQRT(SUMSQ(Δεδομένα!D$2:D$8)) -> 0.13867505 | E7: =Δεδομένα!E6 / SQRT(SUMSQ(Δεδομένα!E$2:E$8)) -> 0 | F7: =Δεδομένα!F6 / SQRT(SUMSQ(Δεδομένα!F$2:F$8)) -> 0 | G7: =Δεδομένα!G6 / SQRT(SUMSQ(Δεδομένα!G$2:G$8)) -> 0 | H7: =Δεδομένα!H6 / SQRT(SUMSQ(Δεδομένα!H$2:H$8)) -> 0 | I7: =Δεδομένα!I6 / SQRT(SUMSQ(Δεδομένα!I$2:I$8)) -> 0 | ... K7: =Δεδομένα!K6 / SQRT(SUMSQ(Δεδομένα!K$2:K$8)) -> 0.37525021
A8: Z | B8: =Δεδομένα!B7 / SQRT(SUMSQ(Δεδομένα!B$2:B$8)) -> 0.48428059 | C8: =Δεδομένα!C7 / SQRT(SUMSQ(Δεδομένα!C$2:C$8)) -> 0.47592076 | D8: =Δεδομένα!D7 / SQRT(SUMSQ(Δεδομένα!D$2:D$8)) -> 0.41602515 | E8: =Δεδομένα!E7 / SQRT(SUMSQ(Δεδομένα!E$2:E$8)) -> 0.62554324 | F8: =Δεδομένα!F7 / SQRT(SUMSQ(Δεδομένα!F$2:F$8)) -> 0.57735027 | G8: =Δεδομένα!G7 / SQRT(SUMSQ(Δεδομένα!G$2:G$8)) -> 0.40572041 | H8: =Δεδομένα!H7 / SQRT(SUMSQ(Δεδομένα!H$2:H$8)) -> 0.84818893 | I8: =Δεδομένα!I6 / SQRT(SUMSQ(Δεδομένα!I$2:I$8)) -> 0 | J8: =Δεδομένα!J7 / SQRT(SUMSQ(Δεδομένα!J$2:J$8)) -> 0.47434165 | K8: =Δεδομένα!K7 / SQRT(SUMSQ(Δεδομένα!K$2:K$8)) -> 0.37808585
A9: H | B9: =Δεδομένα!B8 / SQRT(SUMSQ(Δεδομένα!B$2:B$8)) -> 0.24214029 | C9: =Δεδομένα!C8 / SQRT(SUMSQ(Δεδομένα!C$2:C$8)) -> 0.23796038 | D9: =Δεδομένα!D8 / SQRT(SUMSQ(Δεδομένα!D$2:D$8)) -> 0.2773501 | E9: =Δεδομένα!E8 / SQRT(SUMSQ(Δεδομένα!E$2:E$8)) -> 0 | F9: =Δεδομένα!F8 / SQRT(SUMSQ(Δεδομένα!F$2:F$8)) -> 0 | G9: =Δεδομένα!G8 / SQRT(SUMSQ(Δεδομένα!G$2:G$8)) -> 0.020286021 | H9: =Δεδομένα!H8 / SQRT(SUMSQ(Δεδομένα!H$2:H$8)) -> 0.084818893 | I9: =Δεδομένα!I8 / SQRT(SUMSQ(Δεδομένα!I$2:I$8)) -> 0.16903085 | ... K9: =Δεδομένα!K8 / SQRT(SUMSQ(Δεδομένα!K$2:K$8)) -> 0.37241456
A11: Σταθμισμένος Πίνακας (Weighted Normalized Matrix) (ROC)
A12: Εναλλακτικές / Χαρακτηριστικά | B12: Ενοίκιο (Κ) | C12: Εμβαδό (Ο) | D12: Δωμάτια (Ο) | E12: Πάρκινγκ (Ο) | F12: Θέρμανση (Ο) | G12: Απόστ. ΜΜΜ (Κ) | H12: Απόστ. Αγορά (Κ) | I12: Κατάσταση (Ο) | J12: Όροφος (Ο) | K12: Έτος (Ο) | L12: Si+ (Απόσταση από το Ιδανικό) | M12: Si- (Απόσταση από το Αρνητικό Ιδανικό) | N12: Ci (Τελική Επίδοση)
A13: A | B13: =B3 * Βάρη!$E$2 -> 0.11820482 | C13: =C3 * Βάρη!$E$3 -> 0.082624602 | D13: =D3 * Βάρη!$E$4 -> 0.059449994 | E13: =E3 * Βάρη!$E$5 -> 0.019975681 | F13: =F3 * Βάρη!$E$6 -> 0 | G13: =G3 * Βάρη!$E$7 -> 0.011116739 | H13: =H3 * Βάρη!$E$8 -> 0.014249574 | I13: =I3 * Βάρη!$E$9 -> 0.02860002 | J13: =J3 * Βάρη!$E$10 -> 0.0062613098 | K13: =K3 * Βάρη!$E$11 -> 0.0079576674 | L13: =SQRT(SUMXMY2(B13:K13, $B$20:$K$20)) -> 0.085321446 | M13: =SQRT(SUMXMY2(B13:K13, $B$21:$K$21)) -> 0.11777382 | N13: =M13 / (L13 + M13) -> 0.57989445
A14: B | B14: =B4 * Βάρη!$E$2 -> 0.094563856 | C14: =C4 * Βάρη!$E$3 -> 0.050492813 | D14: =D4 * Βάρη!$E$4 -> 0.039633329 | E14: =E4 * Βάρη!$E$5 -> 0.0099878404 | F14: =F4 * Βάρη!$E$6 -> 0 | G14: =G4 * Βάρη!$E$7 -> 0.044466957 | H14: =H4 * Βάρη!$E$8 -> 0 | I14: =I4 * Βάρη!$E$9 -> 0.02860002 | J14: =J4 * Βάρη!$E$10 -> 0.0046959823 | K14: =K4 * Βάρη!$E$11 -> 0.0080374435 | L14: =SQRT(SUMXMY2(B14:K14, $B$20:$K$20)) -> 0.1047713 | M14: =SQRT(SUMXMY2(B14:K14, $B$21:$K$21)) -> 0.097412516 | N14: =M14 / (L14 + M14) -> 0.48180175
A15: Γ | B15: =B5 * Βάρη!$E$2 -> 0.082743374 | C15: =C5 * Βάρη!$E$3 -> 0.06426358 | D15: =D5 * Βάρη!$E$4 -> 0.059449994 | E15: =E5 * Βάρη!$E$5 -> 0 | F15: =F5 * Βάρη!$E$6 -> 0.037296827 | G15: =G5 * Βάρη!$E$7 -> 0.0044466957 | H15: =H5 * Βάρη!$E$8 -> 0.0056998296 | I15: =I5 * Βάρη!$E$9 -> 0.01430001 | J15: =J5 * Βάρη!$E$10 -> 0.0031306549 | K15: =K5 * Βάρη!$E$11 -> 0.0079975555 | L15: =SQRT(SUMXMY2(B15:K15, $B$20:$K$20)) -> 0.076543673 | M15: =SQRT(SUMXMY2(B15:K15, $B$21:$K$21)) -> 0.1367954 | N15: =M15 / (L15 + M15) -> 0.64121119
A16: Δ | B16: =B6 * Βάρη!$E$2 -> 0.16548675 | C16: =C6 * Βάρη!$E$3 -> 0.11016614 | D16: =D6 * Βάρη!$E$4 -> 0.079266658 | E16: =E6 * Βάρη!$E$5 -> 0.029963521 | F16: =F6 * Βάρη!$E$6 -> 0.037296827 | G16: =G6 * Βάρη!$E$7 -> 0.088933915 | H16: =H6 * Βάρη!$E$8 -> 0.0085497444 | I16: =I6 * Βάρη!$E$9 -> 0.05720004 | J16: =J6 * Βάρη!$E$10 -> 0.0015653274 | K16: =K6 * Βάρη!$E$11 -> 0.0080773316 | L16: =SQRT(SUMXMY2(B16:K16, $B$20:$K$20)) -> 0.13900367 | M16: =SQRT(SUMXMY2(B16:K16, $B$21:$K$21)) -> 0.12483929 | N16: =M16 / (L16 + M16) -> 0.47315757
A17: E | B17: =B7 * Βάρη!$E$2 -> 0.05910241 | C17: =C7 * Βάρη!$E$3 -> 0.03213179 | D17: =D7 * Βάρη!$E$4 -> 0.019816665 | E17: =E7 * Βάρη!$E$5 -> 0 | F17: =F7 * Βάρη!$E$6 -> 0 | G17: =G7 * Βάρη!$E$7 -> 0 | H17: =H7 * Βάρη!$E$8 -> 0 | I17: =I7 * Βάρη!$E$9 -> 0 | J17: =J7 * Βάρη!$E$10 -> 0 | K17: =K7 * Βάρη!$E$11 -> 0.0079177794 | L17: =SQRT(SUMXMY2(B17:K17, $B$20:$K$20)) -> 0.12338396 | M17: =SQRT(SUMXMY2(B17:K17, $B$21:$K$21)) -> 0.14155943 | N17: =M17 / (L17 + M17) -> 0.53430068
A18: Z | B18: =B8 * Βάρη!$E$2 -> 0.14184578 | C18: =C8 * Βάρη!$E$3 -> 0.091805114 | D18: =D8 * Βάρη!$E$4 -> 0.059449994 | E18: =E8 * Βάρη!$E$5 -> 0.029963521 | F18: =F8 * Βάρη!$E$6 -> 0.037296827 | G18: =G8 * Βάρη!$E$7 -> 0.044466957 | H18: =H8 * Βάρη!$E$8 -> 0.028499148 | I18: =I8 * Βάρη!$E$9 -> 0 | J18: =J8 * Βάρη!$E$10 -> 0.0046959823 | K18: =K8 * Βάρη!$E$11 -> 0.0079776115 | L18: =SQRT(SUMXMY2(B18:K18, $B$20:$K$20)) -> 0.11679088 | M18: =SQRT(SUMXMY2(B18:K18, $B$21:$K$21)) -> 0.099894166 | N18: =M18 / (L18 + M18) -> 0.46101089
A19: H | B19: =B9 * Βάρη!$E$2 -> 0.070922892 | C19: =C9 * Βάρη!$E$3 -> 0.045902557 | D19: =D9 * Βάρη!$E$4 -> 0.039633329 | E19: =E9 * Βάρη!$E$5 -> 0 | F19: =F9 * Βάρη!$E$6 -> 0 | G19: =G9 * Βάρη!$E$7 -> 0.0022233479 | H19: =H9 * Βάρη!$E$8 -> 0.0028499148 | I19: =I9 * Βάρη!$E$9 -> 0.01430001 | J19: =J9 * Βάρη!$E$10 -> 0.0015653274 | K19: =K9 * Βάρη!$E$11 -> 0.0078579473 | L19: =SQRT(SUMXMY2(B19:K19, $B$20:$K$20)) -> 0.10002388 | M19: =SQRT(SUMXMY2(B19:K19, $B$21:$K$21)) -> 0.13382153 | N19: =M19 / (L19 + M19) -> 0.57226495
A20: Ιδανική (Α+) | B20: =MIN(B13:B19) -> 0.05910241 | C20: =MAX(C13:C19) -> 0.11016614 | D20: =MAX(D13:D19) -> 0.079266658 | E20: =MAX(E13:E19) -> 0.029963521 | F20: =MAX(F13:F19) -> 0.037296827 | G20: =MIN(G13:G19) -> 0 | H20: =MIN(H13:H19) -> 0 | I20: =MAX(I13:I19) -> 0.05720004 | J20: =MAX(J13:J19) -> 0.0062613098 | K20: =MAX(K13:K19) -> 0.0080773316
A21: Αρνητική Ιδανική (A-) | B21: =MAX(B13:B19) -> 0.16548675 | C21: =MIN(C13:C19) -> 0.03213179 | D21: =MIN(D13:D19) -> 0.019816665 | E21: =MIN(E13:E19) -> 0 | F21: =MIN(F13:F19) -> 0 | G21: =MAX(G13:G19) -> 0.088933915 | H21: =MAX(H13:H19) -> 0.028499148 | I21: =MIN(I13:I19) -> 0 | J21: =MIN(J13:J19) -> 0 | K21: =MIN(K13:K19) -> 0.0078579473
A23: Σταθμισμένος Πίνακας (Weighted Normalized Matrix) (RS)
A24: Εναλλακτικές / Χαρακτηριστικά | B24: Ενοίκιο (Κ) | C24: Εμβαδό (Ο) | D24: Δωμάτια (Ο) | E24: Πάρκινγκ (Ο) | F24: Θέρμανση (Ο) | G24: Απόστ. ΜΜΜ (Κ) | H24: Απόστ. Αγορά (Κ) | I24: Κατάσταση (Ο) | J24: Όροφος (Ο) | K24: Έτος (Ο) | L24: Si+ (Απόσταση από το Ιδανικό) | M24: Si- (Απόσταση από το Αρνητικό Ιδανικό) | N24: Ci (Τελική Επίδοση)
A25: A | B25: =B3 * Βάρη!$C$2 -> 0.073375847 | C25: =C3 * Βάρη!$C$3 -> 0.070090148 | D25: =D3 * Βάρη!$C$4 -> 0.060512749 | E25: =E3 * Βάρη!$C$5 -> 0.030329369 | F25: =F3 * Βάρη!$C$6 -> 0 | G25: =G3 * Βάρη!$C$7 -> 0.012909286 | H25: =H3 * Βάρη!$C$8 -> 0.023132425 | I25: =I3 * Βάρη!$C$9 -> 0.036879458 | J25: =J3 * Βάρη!$C$10 -> 0.022998383 | K25: =K3 * Βάρη!$C$11 -> 0.0068571025 | L25: =SQRT(SUMXMY2(B25:K25, $B$32:$K$32)) -> 0.085705132 | M25: =SQRT(SUMXMY2(B25:K25, $B$33:$K$33)) -> 0.12583084 | N25: =M25 / (L25 + M25) -> 0.5948437
A26: B | B26: =B4 * Βάρη!$C$2 -> 0.058700677 | C26: =C4 * Βάρη!$C$3 -> 0.042832868 | D26: =D4 * Βάρη!$C$4 -> 0.040341832 | E26: =E4 * Βάρη!$C$5 -> 0.015164685 | F26: =F4 * Βάρη!$C$6 -> 0 | G26: =G4 * Βάρη!$C$7 -> 0.051637143 | H26: =H4 * Βάρη!$C$8 -> 0 | I26: =I4 * Βάρη!$C$9 -> 0.036879458 | J26: =J4 * Βάρη!$C$10 -> 0.017248787 | K26: =K4 * Βάρη!$C$11 -> 0.0069258454 | L26: =SQRT(SUMXMY2(B26:K26, $B$32:$K$32)) -> 0.11139442 | M26: =SQRT(SUMXMY2(B26:K26, $B$33:$K$33)) -> 0.096343904 | N26: =M26 / (L26 + M26) -> 0.46377531
A27: Γ | B27: =B5 * Βάρη!$C$2 -> 0.051363093 | C27: =C5 * Βάρη!$C$3 -> 0.054514559 | D27: =D5 * Βάρη!$C$4 -> 0.060512749 | E27: =E5 * Βάρη!$C$5 -> 0 | F27: =F5 * Βάρη!$C$6 -> 0.052486388 | G27: =G5 * Βάρη!$C$7 -> 0.0051637143 | H27: =H5 * Βάρη!$C$8 -> 0.0092529701 | I27: =I5 * Βάρη!$C$9 -> 0.018439729 | J27: =J5 * Βάρη!$C$10 -> 0.011499191 | K27: =K5 * Βάρη!$C$11 -> 0.0068914739 | L27: =SQRT(SUMXMY2(B27:K27, $B$32:$K$32)) -> 0.086677038 | M27: =SQRT(SUMXMY2(B27:K27, $B$33:$K$33)) -> 0.13867676 | N27: =M27 / (L27 + M27) -> 0.61537352
A28: Δ | B28: =B6 * Βάρη!$C$2 -> 0.10272619 | C28: =C6 * Βάρη!$C$3 -> 0.09345353 | D28: =D6 * Βάρη!$C$4 -> 0.080683665 | E28: =E6 * Βάρη!$C$5 -> 0.045494054 | F28: =F6 * Βάρη!$C$6 -> 0.052486388 | G28: =G6 * Βάρη!$C$7 -> 0.10327429 | H28: =H6 * Βάρη!$C$8 -> 0.013879455 | I28: =I6 * Βάρη!$C$9 -> 0.073758917 | J28: =J6 * Βάρη!$C$10 -> 0.0057495957 | K28: =K6 * Βάρη!$C$11 -> 0.0069602168 | L28: =SQRT(SUMXMY2(B28:K28, $B$32:$K$32)) -> 0.12456641 | M28: =SQRT(SUMXMY2(B28:K28, $B$33:$K$33)) -> 0.13924996 | N28: =M28 / (L28 + M28) -> 0.52782911
A29: E | B29: =B7 * Βάρη!$C$2 -> 0.036687923 | C29: =C7 * Βάρη!$C$3 -> 0.02725728 | D29: =D7 * Βάρη!$C$4 -> 0.020170916 | E29: =E7 * Βάρη!$C$5 -> 0 | F29: =F7 * Βάρη!$C$6 -> 0 | G29: =G7 * Βάρη!$C$7 -> 0 | H29: =H7 * Βάρη!$C$8 -> 0 | I29: =I7 * Βάρη!$C$9 -> 0 | J29: =J7 * Βάρη!$C$10 -> 0 | K29: =K7 * Βάρη!$C$11 -> 0.006822731 | L29: =SQRT(SUMXMY2(B29:K29, $B$32:$K$32)) -> 0.13725009 | M29: =SQRT(SUMXMY2(B29:K29, $B$33:$K$33)) -> 0.13102316 | N29: =M29 / (L29 + M29) -> 0.48839442
A30: Z | B30: =B8 * Βάρη!$C$2 -> 0.088051016 | C30: =C8 * Βάρη!$C$3 -> 0.077877942 | D30: =D8 * Βάρη!$C$4 -> 0.060512749 | E30: =E8 * Βάρη!$C$5 -> 0.045494054 | F30: =F8 * Βάρη!$C$6 -> 0.052486388 | G30: =G8 * Βάρη!$C$7 -> 0.051637143 | H30: =H8 * Βάρη!$C$8 -> 0.046264851 | I30: =I8 * Βάρη!$C$9 -> 0 | J30: =J8 * Βάρη!$C$10 -> 0.017248787 | K30: =K8 * Βάρη!$C$11 -> 0.0068742882 | L30: =SQRT(SUMXMY2(B30:K30, $B$32:$K$32)) -> 0.11648136 | M30: =SQRT(SUMXMY2(B30:K30, $B$33:$K$33)) -> 0.11042523 | N30: =M30 / (L30 + M30) -> 0.48665502
A31: H | B31: =B9 * Βάρη!$C$2 -> 0.044025508 | C31: =C9 * Βάρη!$C$3 -> 0.038938971 | D31: =D9 * Βάρη!$C$4 -> 0.040341832 | E31: =E9 * Βάρη!$C$5 -> 0 | F31: =F9 * Βάρη!$C$6 -> 0 | G31: =G9 * Βάρη!$C$7 -> 0.0025818572 | H31: =H9 * Βάρη!$C$8 -> 0.0046264851 | I31: =I9 * Βάρη!$C$9 -> 0.018439729 | J31: =J9 * Βάρη!$C$10 -> 0.0057495957 | K31: =K9 * Βάρη!$C$11 -> 0.0067711739 | L31: =SQRT(SUMXMY2(B31:K31, $B$32:$K$32)) -> 0.11341741 | M31: =SQRT(SUMXMY2(B31:K31, $B$33:$K$33)) -> 0.12741624 | N31: =M31 / (L31 + M31) -> 0.52906326
A32: Ιδανική (Α+) | B32: =MIN(B25:B31) -> 0.036687923 | C32: =MAX(C25:C31) -> 0.09345353 | D32: =MAX(D25:D31) -> 0.080683665 | E32: =MAX(E25:E31) -> 0.045494054 | F32: =MAX(F25:F31) -> 0.052486388 | G32: =MIN(G25:G31) -> 0 | H32: =MIN(H25:H31) -> 0 | I32: =MAX(I25:I31) -> 0.073758917 | J32: =MAX(J25:J31) -> 0.022998383 | K32: =MAX(K25:K31) -> 0.0069602168
A33: Αρνητική Ιδανική (A-) | B33: =MAX(B25:B31) -> 0.10272619 | C33: =MIN(C25:C31) -> 0.02725728 | D33: =MIN(D25:D31) -> 0.020170916 | E33: =MIN(E25:E31) -> 0 | F33: =MIN(F25:F31) -> 0 | G33: =MAX(G25:G31) -> 0.10327429 | H33: =MAX(H25:H31) -> 0.046264851 | I33: =MIN(I25:I31) -> 0 | J33: =MIN(J25:J31) -> 0 | K33: =MIN(K25:K31) -> 0.0067711739
A35: Σταθμισμένος Πίνακας (Weighted Normalized Matrix) (RR)
A36: Εναλλακτικές / Χαρακτηριστικά | B36: Ενοίκιο (Κ) | C36: Εμβαδό (Ο) | D36: Δωμάτια (Ο) | E36: Πάρκινγκ (Ο) | F36: Θέρμανση (Ο) | G36: Απόστ. ΜΜΜ (Κ) | H36: Απόστ. Αγορά (Κ) | I36: Κατάσταση (Ο) | J36: Όροφος (Ο) | K36: Έτος (Ο) | L36: Si+ (Απόσταση από το Ιδανικό) | M36: Si- (Απόσταση από το Αρνητικό Ιδανικό) | N36: Ci (Τελική Επίδοση)
A37: A | B37: =B3 * Βάρη!$D$2 -> 0.13778475 | C37: =C3 * Βάρη!$D$3 -> 0.073119379 | D37: =D3 * Βάρη!$D$4 -> 0.04734604 | E37: =E3 * Βάρη!$D$5 -> 0.020340114 | F37: =F3 * Βάρη!$D$6 -> 0 | G37: =G3 * Βάρη!$D$7 -> 0.0086574942 | H37: =H3 * Βάρη!$D$8 -> 0.018099141 | I37: =I3 * Βάρη!$D$9 -> 0.023084013 | J37: =J3 * Βάρη!$D$10 -> 0.023992352 | K37: =K3 * Βάρη!$D$11 -> 0.012876228 | L37: =SQRT(SUMXMY2(B37:K37, $B$44:$K$44)) -> 0.087792156 | M37: =SQRT(SUMXMY2(B37:K37, $B$45:$K$45)) -> 0.1074848 | N37: =M37 / (L37 + M37) -> 0.55042236
A38: B | B38: =B4 * Βάρη!$D$2 -> 0.1102278 | C38: =C4 * Βάρη!$D$3 -> 0.044684065 | D38: =D4 * Βάρη!$D$4 -> 0.031564027 | E38: =E4 * Βάρη!$D$5 -> 0.010170057 | F38: =F4 * Βάρη!$D$6 -> 0 | G38: =G4 * Βάρη!$D$7 -> 0.034629977 | H38: =H4 * Βάρη!$D$8 -> 0 | I38: =I4 * Βάρη!$D$9 -> 0.023084013 | J38: =J4 * Βάρη!$D$10 -> 0.017994264 | K38: =K4 * Βάρη!$D$11 -> 0.013005313 | L38: =SQRT(SUMXMY2(B38:K38, $B$44:$K$44)) -> 0.093566857 | M38: =SQRT(SUMXMY2(B38:K38, $B$45:$K$45)) -> 0.10400622 | N38: =M38 / (L38 + M38) -> 0.52641899
A39: Γ | B39: =B5 * Βάρη!$D$2 -> 0.096449324 | C39: =C5 * Βάρη!$D$3 -> 0.056870628 | D39: =D5 * Βάρη!$D$4 -> 0.04734604 | E39: =E5 * Βάρη!$D$5 -> 0 | F39: =F5 * Βάρη!$D$6 -> 0.032852881 | G39: =G5 * Βάρη!$D$7 -> 0.0034629977 | H39: =H5 * Βάρη!$D$8 -> 0.0072396562 | I39: =I5 * Βάρη!$D$9 -> 0.011542006 | J39: =J5 * Βάρη!$D$10 -> 0.011996176 | K39: =K5 * Βάρη!$D$11 -> 0.012940771 | L39: =SQRT(SUMXMY2(B39:K39, $B$44:$K$44)) -> 0.070687735 | M39: =SQRT(SUMXMY2(B39:K39, $B$45:$K$45)) -> 0.13278425 | N39: =M39 / (L39 + M39) -> 0.6525923
A40: Δ | B40: =B6 * Βάρη!$D$2 -> 0.19289865 | C40: =C6 * Βάρη!$D$3 -> 0.097492506 | D40: =D6 * Βάρη!$D$4 -> 0.063128054 | E40: =E6 * Βάρη!$D$5 -> 0.03051017 | F40: =F6 * Βάρη!$D$6 -> 0.032852881 | G40: =G6 * Βάρη!$D$7 -> 0.069259954 | H40: =H6 * Βάρη!$D$8 -> 0.010859484 | I40: =I6 * Βάρη!$D$9 -> 0.046168025 | J40: =J6 * Βάρη!$D$10 -> 0.005998088 | K40: =K6 * Βάρη!$D$11 -> 0.013069856 | L40: =SQRT(SUMXMY2(B40:K40, $B$44:$K$44)) -> 0.14358349 | M40: =SQRT(SUMXMY2(B40:K40, $B$45:$K$45)) -> 0.1087675 | N40: =M40 / (L40 + M40) -> 0.43101674
A41: E | B41: =B7 * Βάρη!$D$2 -> 0.068892375 | C41: =C7 * Βάρη!$D$3 -> 0.028435314 | D41: =D7 * Βάρη!$D$4 -> 0.015782013 | E41: =E7 * Βάρη!$D$5 -> 0 | F41: =F7 * Βάρη!$D$6 -> 0 | G41: =G7 * Βάρη!$D$7 -> 0 | H41: =H7 * Βάρη!$D$8 -> 0 | I41: =I7 * Βάρη!$D$9 -> 0 | J41: =J7 * Βάρη!$D$10 -> 0 | K41: =K7 * Βάρη!$D$11 -> 0.012811686 | L41: =SQRT(SUMXMY2(B41:K41, $B$44:$K$44)) -> 0.10829548 | M41: =SQRT(SUMXMY2(B41:K41, $B$45:$K$45)) -> 0.14657702 | N41: =M41 / (L41 + M41) -> 0.57509938
A42: Z | B42: =B8 * Βάρη!$D$2 -> 0.1653417 | C42: =C8 * Βάρη!$D$3 -> 0.081243755 | D42: =D8 * Βάρη!$D$4 -> 0.04734604 | E42: =E8 * Βάρη!$D$5 -> 0.03051017 | F42: =F8 * Βάρη!$D$6 -> 0.032852881 | G42: =G8 * Βάρη!$D$7 -> 0.034629977 | H42: =H8 * Βάρη!$D$8 -> 0.036198281 | I42: =I8 * Βάρη!$D$9 -> 0 | J42: =J8 * Βάρη!$D$10 -> 0.017994264 | K42: =K8 * Βάρη!$D$11 -> 0.012908499 | L42: =SQRT(SUMXMY2(B42:K42, $B$44:$K$44)) -> 0.12038524 | M42: =SQRT(SUMXMY2(B42:K42, $B$45:$K$45)) -> 0.089875766 | N42: =M42 / (L42 + M42) -> 0.42744856
A43: H | B43: =B9 * Βάρη!$D$2 -> 0.082670849 | C43: =C9 * Βάρη!$D$3 -> 0.040621877 | D43: =D9 * Βάρη!$D$4 -> 0.031564027 | E43: =E9 * Βάρη!$D$5 -> 0 | F43: =F9 * Βάρη!$D$6 -> 0 | G43: =G9 * Βάρη!$D$7 -> 0.0017314988 | H43: =H9 * Βάρη!$D$8 -> 0.0036198281 | I43: =I9 * Βάρη!$D$9 -> 0.011542006 | J43: =J9 * Βάρη!$D$10 -> 0.005998088 | K43: =K9 * Βάρη!$D$11 -> 0.012714872 | L43: =SQRT(SUMXMY2(B43:K43, $B$44:$K$44)) -> 0.08927243 | M43: =SQRT(SUMXMY2(B43:K43, $B$45:$K$45)) -> 0.13541933 | N43: =M43 / (L43 + M43) -> 0.60268935
...

Sheet AHP
B2: Ενοίκιο | C2: Εμβαδό | D2: Δωμάτια | E2: Κατάσταση | F2: Όροφος | G2: Θέρμανση | H2: Πάρκινγκ | I2: ΜΜΜ | J2: Αγορά | K2: Έτος
A3: Ενοίκιο | B3: 1 | C3: 2 | D3: 3 | E3: 4 | F3: 5 | G3: 6 | H3: 4 | I3: 4 | J3: 4 | K3: 5
A4: Εμβαδό | B4: {=1/TRANSPOSE($C$3:$K$3)} -> 0.5 | C4: 1 | D4: 2 | E4: 3 | F4: 4 | G4: 5 | H4: 6 | I4: 4 | J4: 4 | K4: 5
A5: Δωμάτια | B5: 0.33333333 | C5: {=1/TRANSPOSE($D$4:$K$4)} -> 0.5 | D5: 1 | E5: 2 | F5: 3 | G5: 4 | H5: 5 | I5: 3 | J5: 3 | K5: 4
A6: Κατάσταση | B6: 0.25 | C6: 0.33333333 | D6: {=1/TRANSPOSE($E$5:$K$5)} -> 0.5 | E6: 1 | F6: 2 | G6: 3 | H6: 4 | I6: 5 | J6: 5 | K6: 6
A7: Όροφος | B7: 0.2 | C7: 0.25 | D7: 0.33333333 | E7: {=1/TRANSPOSE($F$6:$K$6)} -> 0.5 | F7: 1 | G7: 2 | H7: 3 | I7: 4 | J7: 4 | K7: 5
A8: Θέρμανση | B8: 0.16666667 | C8: 0.2 | D8: 0.25 | E8: 0.33333333 | F8: {=1/TRANSPOSE($G$7:$K$7)} -> 0.5 | G8: 1 | H8: 2 | I8: 3 | J8: 3 | K8: 4
A9: Πάρκινγκ | B9: 0.25 | C9: 0.16666667 | D9: 0.2 | E9: 0.25 | F9: 0.33333333 | G9: {=1/TRANSPOSE($H$8:$K$8)} -> 0.5 | H9: 1 | I9: 2 | J9: 2 | K9: 3
A10: ΜΜΜ | B10: 0.25 | C10: 0.25 | D10: 0.33333333 | E10: 0.2 | F10: 0.25 | G10: 0.33333333 | H10: {=1/TRANSPOSE($I$9:$K$9)} -> 0.5 | I10: 1 | J10: 1 | K10: 2
A11: Αγορά | B11: 0.25 | C11: 0.25 | D11: 0.33333333 | E11: 0.2 | F11: 0.25 | G11: 0.33333333 | H11: 0.5 | I11: {=1/TRANSPOSE($J$10:$K$10)} -> 1 | J11: 1 | K11: 2
A12: Έτος | B12: 0.2 | C12: 0.2 | D12: 0.25 | E12: 0.16666667 | F12: 0.2 | G12: 0.25 | H12: 0.33333333 | I12: 0.5 | J12: {=1/TRANSPOSE($K$11:$K11)} -> 0.5 | K12: 1
A13: Αθροισμα | B13: =SUM(B3:B12) -> 3.4 | C13: =SUM(C3:C12) -> 5.15 | D13: =SUM(D3:D12) -> 8.2 | E13: =SUM(E3:E12) -> 11.65 | F13: =SUM(F3:F12) -> 16.533333 | G13: =SUM(G3:G12) -> 22.416667 | H13: =SUM(H3:H12) -> 26.333333 | I13: =SUM(I3:I12) -> 27.5 | ... K13: =SUM(K3:K12) -> 37
A15: Κανονικοποιημένος Πίνακα (Normalized Matrix)
B16: Ενοίκιο | C16: Εμβαδό | D16: Δωμάτια | E16: Κατάσταση | F16: Όροφος | G16: Θέρμανση | H16: Πάρκινγκ | I16: ΜΜΜ | J16: Αγορά | K16: Έτος | L16: Μ.Ο.
A17: Ενοίκιο | B17: =B3/B$13 -> 0.29411765 | C17: =C3/C$13 -> 0.38834951 | D17: =D3/D$13 -> 0.36585366 | E17: =E3/E$13 -> 0.34334764 | F17: =F3/F$13 -> 0.30241935 | G17: =G3/G$13 -> 0.26765799 | H17: =H3/H$13 -> 0.15189873 | I17: =I3/I$13 -> 0.14545455 | ... K17: =K3/K$13 -> 0.13513514 | L17: =AVERAGE(B17:K17) -> 0.25396888
A18: Εμβαδό | B18: =B4/B$13 -> 0.14705882 | C18: =C4/C$13 -> 0.19417476 | D18: =D4/D$13 -> 0.24390244 | E18: =E4/E$13 -> 0.25751073 | F18: =F4/F$13 -> 0.24193548 | G18: =G4/G$13 -> 0.22304833 | H18: =H4/H$13 -> 0.2278481 | I18: =I4/I$13 -> 0.14545455 | ... K18: =K4/K$13 -> 0.13513514 | L18: =AVERAGE(B18:K18) -> 0.19615229
A19: Δωμάτια | B19: =B5/B$13 -> 0.098039216 | C19: =C5/C$13 -> 0.097087379 | D19: =D5/D$13 -> 0.12195122 | E19: =E5/E$13 -> 0.17167382 | F19: =F5/F$13 -> 0.18145161 | G19: =G5/G$13 -> 0.17843866 | H19: =H5/H$13 -> 0.18987342 | I19: =I5/I$13 -> 0.10909091 | ... K19: =K5/K$13 -> 0.10810811 | L19: =AVERAGE(B19:K19) -> 0.13648053
A20: Κατάσταση | B20: =B6/B$13 -> 0.073529412 | C20: =C6/C$13 -> 0.064724919 | D20: =D6/D$13 -> 0.06097561 | E20: =E6/E$13 -> 0.08583691 | F20: =F6/F$13 -> 0.12096774 | G20: =G6/G$13 -> 0.133829 | H20: =H6/H$13 -> 0.15189873 | I20: =I6/I$13 -> 0.18181818 | ... K20: =K6/K$13 -> 0.16216216 | L20: =AVERAGE(B20:K20) -> 0.12175608
A21: Όροφος | B21: =B7/B$13 -> 0.058823529 | C21: =C7/C$13 -> 0.048543689 | D21: =D7/D$13 -> 0.040650407 | E21: =E7/E$13 -> 0.042918455 | F21: =F7/F$13 -> 0.060483871 | G21: =G7/G$13 -> 0.089219331 | H21: =H7/H$13 -> 0.11392405 | I21: =I7/I$13 -> 0.14545455 | ... K21: =K7/K$13 -> 0.13513514 | L21: =AVERAGE(B21:K21) -> 0.088060756
A22: Θέρμανση | B22: =B8/B$13 -> 0.049019608 | C22: =C8/C$13 -> 0.038834951 | D22: =D8/D$13 -> 0.030487805 | E22: =E8/E$13 -> 0.028612303 | F22: =F8/F$13 -> 0.030241935 | G22: =G8/G$13 -> 0.044609665 | H22: =H8/H$13 -> 0.075949367 | I22: =I8/I$13 -> 0.10909091 | ... K22: =K8/K$13 -> 0.10810811 | L22: =AVERAGE(B22:K22) -> 0.062404556
A23: Πάρκινγκ | B23: =B9/B$13 -> 0.073529412 | C23: =C9/C$13 -> 0.03236246 | D23: =D9/D$13 -> 0.024390244 | E23: =E9/E$13 -> 0.021459227 | F23: =F9/F$13 -> 0.02016129 | G23: =G9/G$13 -> 0.022304833 | H23: =H9/H$13 -> 0.037974684 | I23: =I9/I$13 -> 0.072727273 | ... K23: =K9/K$13 -> 0.081081081 | L23: =AVERAGE(B23:K23) -> 0.045871778
A24: ΜΜΜ | B24: =B10/B$13 -> 0.073529412 | C24: =C10/C$13 -> 0.048543689 | D24: =D10/D$13 -> 0.040650407 | E24: =E10/E$13 -> 0.017167382 | F24: =F10/F$13 -> 0.015120968 | G24: =G10/G$13 -> 0.014869888 | H24: =H10/H$13 -> 0.018987342 | I24: =I10/I$13 -> 0.036363636 | ... K24: =K10/K$13 -> 0.054054054 | L24: =AVERAGE(B24:K24) -> 0.035565041
A25: Αγορά | B25: =B11/B$13 -> 0.073529412 | C25: =C11/C$13 -> 0.048543689 | D25: =D11/D$13 -> 0.040650407 | E25: =E11/E$13 -> 0.017167382 | F25: =F11/F$13 -> 0.015120968 | G25: =G11/G$13 -> 0.014869888 | H25: =H11/H$13 -> 0.018987342 | I25: =I11/I$13 -> 0.036363636 | ... K25: =K11/K$13 -> 0.054054054 | L25: =AVERAGE(B25:K25) -> 0.035565041
A26: Έτος | B26: =B12/B$13 -> 0.058823529 | C26: =C12/C$13 -> 0.038834951 | D26: =D12/D$13 -> 0.030487805 | E26: =E12/E$13 -> 0.014306152 | F26: =F12/F$13 -> 0.012096774 | G26: =G12/G$13 -> 0.011152416 | H26: =H12/H$13 -> 0.012658228 | I26: =I12/I$13 -> 0.018181818 | ... K26: =K12/K$13 -> 0.027027027 | L26: =AVERAGE(B26:K26) -> 0.024175052
A27: Αθροισμα | B27: =SUM(B17:B26) -> 1 | C27: =SUM(C17:C26) -> 1 | D27: =SUM(D17:D26) -> 1 | E27: =SUM(E17:E26) -> 1 | F27: =SUM(F17:F26) -> 1 | G27: =SUM(G17:G26) -> 1 | H27: =SUM(H17:H26) -> 1 | I27: =SUM(I17:I26) -> 1 | ... K27: =SUM(K17:K26) -> 1 | L27: =AVERAGE(B27:K27) -> 1
A30: 4.4.2
A33: Ενοίκιο (Κόστος)
A34: Εναλλακτικές | B34: Α | C34: Β | D34: Γ | E34: Δ | F34: Ε | G34: Ζ | H34: Η
A35: A | B35: =IF(Κανονικοποίηση!B$2=0, IF(Κανονικοποίηση!$B2=0, 1, 1/9), IF(Κανονικοποίηση!$B2=0, 9, MIN(MAX(Κανονικοποίηση!B$2/Κανονικοποίηση!$B2, 1/9), 9))) -> 1 | C35: =IF(Κανονικοποίηση!C$2=0, IF(Κανονικοποίηση!$B2=0, 1, 1/9), IF(Κανονικοποίηση!$B2=0, 9, MIN(MAX(Κανονικοποίηση!C$2/Κανονικοποίηση!$B2, 1/9), 9))) -> 1.3865546 | D35: =IF(Κανονικοποίηση!D$2=0, IF(Κανονικοποίηση!$B2=0, 1, 1/9), IF(Κανονικοποίηση!$B2=0, 9, MIN(MAX(Κανονικοποίηση!D$2/Κανονικοποίηση!$B2, 1/9), 9))) -> 1.4285714 | E35: =IF(Κανονικοποίηση!E$2=0, IF(Κανονικοποίηση!$B2=0, 1, 1/9), IF(Κανονικοποίηση!$B2=0, 9, MIN(MAX(Κανονικοποίηση!E$2/Κανονικοποίηση!$B2, 1/9), 9))) -> 1.4285714 | F35: =IF(Κανονικοποίηση!F$2=0, IF(Κανονικοποίηση!$B2=0, 1, 1/9), IF(Κανονικοποίηση!$B2=0, 9, MIN(MAX(Κανονικοποίηση!F$2/Κανονικοποίηση!$B2, 1/9), 9))) -> 0.11111111 | G35: =IF(Κανονικοποίηση!G$2=0, IF(Κανονικοποίηση!$B2=0, 1, 1/9), IF(Κανονικοποίηση!$B2=0, 9, MIN(MAX(Κανονικοποίηση!G$2/Κανονικοποίηση!$B2, 1/9), 9))) -> 1.875 | H35: =IF(Κανονικοποίηση!H$2=0, IF(Κανονικοποίηση!$B2=0, 1, 1/9), IF(Κανονικοποίηση!$B2=0, 9, MIN(MAX(Κανονικοποίηση!H$2/Κανονικοποίηση!$B2, 1/9), 9))) -> 1.0714286
A36: B | B36: =IF(Κανονικοποίηση!B$2=0, IF(Κανονικοποίηση!$B3=0, 1, 1/9), IF(Κανονικοποίηση!$B3=0, 9, MIN(MAX(Κανονικοποίηση!B$2/Κανονικοποίηση!$B3, 1/9), 9))) -> 0.66666667 | C36: =IF(Κανονικοποίηση!C$2=0, IF(Κανονικοποίηση!$B3=0, 1, 1/9), IF(Κανονικοποίηση!$B3=0, 9, MIN(MAX(Κανονικοποίηση!C$2/Κανονικοποίηση!$B3, 1/9), 9))) -> 0.92436975 | D36: =IF(Κανονικοποίηση!D$2=0, IF(Κανονικοποίηση!$B3=0, 1, 1/9), IF(Κανονικοποίηση!$B3=0, 9, MIN(MAX(Κανονικοποίηση!D$2/Κανονικοποίηση!$B3, 1/9), 9))) -> 0.95238095 | E36: =IF(Κανονικοποίηση!E$2=0, IF(Κανονικοποίηση!$B3=0, 1, 1/9), IF(Κανονικοποίηση!$B3=0, 9, MIN(MAX(Κανονικοποίηση!E$2/Κανονικοποίηση!$B3, 1/9), 9))) -> 0.95238095 | F36: =IF(Κανονικοποίηση!F$2=0, IF(Κανονικοποίηση!$B3=0, 1, 1/9), IF(Κανονικοποίηση!$B3=0, 9, MIN(MAX(Κανονικοποίηση!F$2/Κανονικοποίηση!$B3, 1/9), 9))) -> 0.11111111 | G36: =IF(Κανονικοποίηση!G$2=0, IF(Κανονικοποίηση!$B3=0, 1, 1/9), IF(Κανονικοποίηση!$B3=0, 9, MIN(MAX(Κανονικοποίηση!G$2/Κανονικοποίηση!$B3, 1/9), 9))) -> 1.25 | H36: =IF(Κανονικοποίηση!H$2=0, IF(Κανονικοποίηση!$B3=0, 1, 1/9), IF(Κανονικοποίηση!$B3=0, 9, MIN(MAX(Κανονικοποίηση!H$2/Κανονικοποίηση!$B3, 1/9), 9))) -> 0.71428571
A37: Γ | B37: =IF(Κανονικοποίηση!B$2=0, IF(Κανονικοποίηση!$B4=0, 1, 1/9), IF(Κανονικοποίηση!$B4=0, 9, MIN(MAX(Κανονικοποίηση!B$2/Κανονικοποίηση!$B4, 1/9), 9))) -> 0.58333333 | C37: =IF(Κανονικοποίηση!C$2=0, IF(Κανονικοποίηση!$B4=0, 1, 1/9), IF(Κανονικοποίηση!$B4=0, 9, MIN(MAX(Κανονικοποίηση!C$2/Κανονικοποίηση!$B4, 1/9), 9))) -> 0.80882353 | D37: =IF(Κανονικοποίηση!D$2=0, IF(Κανονικοποίηση!$B4=0, 1, 1/9), IF(Κανονικοποίηση!$B4=0, 9, MIN(MAX(Κανονικοποίηση!D$2/Κανονικοποίηση!$B4, 1/9), 9))) -> 0.83333333 | E37: =IF(Κανονικοποίηση!E$2=0, IF(Κανονικοποίηση!$B4=0, 1, 1/9), IF(Κανονικοποίηση!$B4=0, 9, MIN(MAX(Κανονικοποίηση!E$2/Κανονικοποίηση!$B4, 1/9), 9))) -> 0.83333333 | F37: =IF(Κανονικοποίηση!F$2=0, IF(Κανονικοποίηση!$B4=0, 1, 1/9), IF(Κανονικοποίηση!$B4=0, 9, MIN(MAX(Κανονικοποίηση!F$2/Κανονικοποίηση!$B4, 1/9), 9))) -> 0.11111111 | G37: =IF(Κανονικοποίηση!G$2=0, IF(Κανονικοποίηση!$B4=0, 1, 1/9), IF(Κανονικοποίηση!$B4=0, 9, MIN(MAX(Κανονικοποίηση!G$2/Κανονικοποίηση!$B4, 1/9), 9))) -> 1.09375 | H37: =IF(Κανονικοποίηση!H$2=0, IF(Κανονικοποίηση!$B4=0, 1, 1/9), IF(Κανονικοποίηση!$B4=0, 9, MIN(MAX(Κανονικοποίηση!H$2/Κανονικοποίηση!$B4, 1/9), 9))) -> 0.625
A38: Δ | B38: =IF(Κανονικοποίηση!B$2=0, IF(Κανονικοποίηση!$B5=0, 1, 1/9), IF(Κανονικοποίηση!$B5=0, 9, MIN(MAX(Κανονικοποίηση!B$2/Κανονικοποίηση!$B5, 1/9), 9))) -> 9 | C38: =IF(Κανονικοποίηση!C$2=0, IF(Κανονικοποίηση!$B5=0, 1, 1/9), IF(Κανονικοποίηση!$B5=0, 9, MIN(MAX(Κανονικοποίηση!C$2/Κανονικοποίηση!$B5, 1/9), 9))) -> 9 | D38: =IF(Κανονικοποίηση!D$2=0, IF(Κανονικοποίηση!$B5=0, 1, 1/9), IF(Κανονικοποίηση!$B5=0, 9, MIN(MAX(Κανονικοποίηση!D$2/Κανονικοποίηση!$B5, 1/9), 9))) -> 9 | E38: =IF(Κανονικοποίηση!E$2=0, IF(Κανονικοποίηση!$B5=0, 1, 1/9), IF(Κανονικοποίηση!$B5=0, 9, MIN(MAX(Κανονικοποίηση!E$2/Κανονικοποίηση!$B5, 1/9), 9))) -> 9 | F38: =IF(Κανονικοποίηση!F$2=0, IF(Κανονικοποίηση!$B5=0, 1, 1/9), IF(Κανονικοποίηση!$B5=0, 9, MIN(MAX(Κανονικοποίηση!F$2/Κανονικοποίηση!$B5, 1/9), 9))) -> 1 | G38: =IF(Κανονικοποίηση!G$2=0, IF(Κανονικοποίηση!$B5=0, 1, 1/9), IF(Κανονικοποίηση!$B5=0, 9, MIN(MAX(Κανονικοποίηση!G$2/Κανονικοποίηση!$B5, 1/9), 9))) -> 9 | H38: =IF(Κανονικοποίηση!H$2=0, IF(Κανονικοποίηση!$B5=0, 1, 1/9), IF(Κανονικοποίηση!$B5=0, 9, MIN(MAX(Κανονικοποίηση!H$2/Κανονικοποίηση!$B5, 1/9), 9))) -> 9
A39: E | B39: =IF(Κανονικοποίηση!B$2=0, IF(Κανονικοποίηση!$B6=0, 1, 1/9), IF(Κανονικοποίηση!$B6=0, 9, MIN(MAX(Κανονικοποίηση!B$2/Κανονικοποίηση!$B6, 1/9), 9))) -> 0.46666667 | C39: =IF(Κανονικοποίηση!C$2=0, IF(Κανονικοποίηση!$B6=0, 1, 1/9), IF(Κανονικοποίηση!$B6=0, 9, MIN(MAX(Κανονικοποίηση!C$2/Κανονικοποίηση!$B6, 1/9), 9))) -> 0.64705882 | D39: =IF(Κανονικοποίηση!D$2=0, IF(Κανονικοποίηση!$B6=0, 1, 1/9), IF(Κανονικοποίηση!$B6=0, 9, MIN(MAX(Κανονικοποίηση!D$2/Κανονικοποίηση!$B6, 1/9), 9))) -> 0.66666667 | E39: =IF(Κανονικοποίηση!E$2=0, IF(Κανονικοποίηση!$B6=0, 1, 1/9), IF(Κανονικοποίηση!$B6=0, 9, MIN(MAX(Κανονικοποίηση!E$2/Κανονικοποίηση!$B6, 1/9), 9))) -> 0.66666667 | F39: =IF(Κανονικοποίηση!F$2=0, IF(Κανονικοποίηση!$B6=0, 1, 1/9), IF(Κανονικοποίηση!$B6=0, 9, MIN(MAX(Κανονικοποίηση!F$2/Κανονικοποίηση!$B6, 1/9), 9))) -> 0.11111111 | G39: =IF(Κανονικοποίηση!G$2=0, IF(Κανονικοποίηση!$B6=0, 1, 1/9), IF(Κανονικοποίηση!$B6=0, 9, MIN(MAX(Κανονικοποίηση!G$2/Κανονικοποίηση!$B6, 1/9), 9))) -> 0.875 | H39: =IF(Κανονικοποίηση!H$2=0, IF(Κανονικοποίηση!$B6=0, 1, 1/9), IF(Κανονικοποίηση!$B6=0, 9, MIN(MAX(Κανονικοποίηση!H$2/Κανονικοποίηση!$B6, 1/9), 9))) -> 0.5
A40: Z | B40: =IF(Κανονικοποίηση!B$2=0, IF(Κανονικοποίηση!$B7=0, 1, 1/9), IF(Κανονικοποίηση!$B7=0, 9, MIN(MAX(Κανονικοποίηση!B$2/Κανονικοποίηση!$B7, 1/9), 9))) -> 2 | C40: =IF(Κανονικοποίηση!C$2=0, IF(Κανονικοποίηση!$B7=0, 1, 1/9), IF(Κανονικοποίηση!$B7=0, 9, MIN(MAX(Κανονικοποίηση!C$2/Κανονικοποίηση!$B7, 1/9), 9))) -> 2.7731092 | D40: =IF(Κανονικοποίηση!D$2=0, IF(Κανονικοποίηση!$B7=0, 1, 1/9), IF(Κανονικοποίηση!$B7=0, 9, MIN(MAX(Κανονικοποίηση!D$2/Κανονικοποίηση!$B7, 1/9), 9))) -> 2.8571429 | E40: =IF(Κανονικοποίηση!E$2=0, IF(Κανονικοποίηση!$B7=0, 1, 1/9), IF(Κανονικοποίηση!$B7=0, 9, MIN(MAX(Κανονικοποίηση!E$2/Κανονικοποίηση!$B7, 1/9), 9))) -> 2.8571429 | F40: =IF(Κανονικοποίηση!F$2=0, IF(Κανονικοποίηση!$B7=0, 1, 1/9), IF(Κανονικοποίηση!$B7=0, 9, MIN(MAX(Κανονικοποίηση!F$2/Κανονικοποίηση!$B7, 1/9), 9))) -> 0.11111111 | G40: =IF(Κανονικοποίηση!G$2=0, IF(Κανονικοποίηση!$B7=0, 1, 1/9), IF(Κανονικοποίηση!$B7=0, 9, MIN(MAX(Κανονικοποίηση!G$2/Κανονικοποίηση!$B7, 1/9), 9))) -> 3.75 | H40: =IF(Κανονικοποίηση!H$2=0, IF(Κανονικοποίηση!$B7=0, 1, 1/9), IF(Κανονικοποίηση!$B7=0, 9, MIN(MAX(Κανονικοποίηση!H$2/Κανονικοποίηση!$B7, 1/9), 9))) -> 2.1428571
A41: H | B41: =IF(Κανονικοποίηση!B$2=0, IF(Κανονικοποίηση!$B8=0, 1, 1/9), IF(Κανονικοποίηση!$B8=0, 9, MIN(MAX(Κανονικοποίηση!B$2/Κανονικοποίηση!$B8, 1/9), 9))) -> 0.51851852 | C41: =IF(Κανονικοποίηση!C$2=0, IF(Κανονικοποίηση!$B8=0, 1, 1/9), IF(Κανονικοποίηση!$B8=0, 9, MIN(MAX(Κανονικοποίηση!C$2/Κανονικοποίηση!$B8, 1/9), 9))) -> 0.71895425 | D41: =IF(Κανονικοποίηση!D$2=0, IF(Κανονικοποίηση!$B8=0, 1, 1/9), IF(Κανονικοποίηση!$B8=0, 9, MIN(MAX(Κανονικοποίηση!D$2/Κανονικοποίηση!$B8, 1/9), 9))) -> 0.74074074 | E41: =IF(Κανονικοποίηση!E$2=0, IF(Κανονικοποίηση!$B8=0, 1, 1/9), IF(Κανονικοποίηση!$B8=0, 9, MIN(MAX(Κανονικοποίηση!E$2/Κανονικοποίηση!$B8, 1/9), 9))) -> 0.74074074 | F41: =IF(Κανονικοποίηση!F$2=0, IF(Κανονικοποίηση!$B8=0, 1, 1/9), IF(Κανονικοποίηση!$B8=0, 9, MIN(MAX(Κανονικοποίηση!F$2/Κανονικοποίηση!$B8, 1/9), 9))) -> 0.11111111 | G41: =IF(Κανονικοποίηση!G$2=0, IF(Κανονικοποίηση!$B8=0, 1, 1/9), IF(Κανονικοποίηση!$B8=0, 9, MIN(MAX(Κανονικοποίηση!G$2/Κανονικοποίηση!$B8, 1/9), 9))) -> 0.97222222 | H41: =IF(Κανονικοποίηση!H$2=0, IF(Κανονικοποίηση!$B8=0, 1, 1/9), IF(Κανονικοποίηση!$B8=0, 9, MIN(MAX(Κανονικοποίηση!H$2/Κανονικοποίηση!$B8, 1/9), 9))) -> 0.55555556
A42: Αθροισμα | B42: =SUM(B35:B41) -> 14.235185 | C42: =SUM(C35:C41) -> 16.25887 | D42: =SUM(D35:D41) -> 16.478836 | E42: =SUM(E35:E41) -> 16.478836 | F42: =SUM(F35:F41) -> 1.6666667 | G42: =SUM(G35:G41) -> 18.815972 | H42: =SUM(H35:H41) -> 14.609127
A44: Κανονικοποιημένος Πίνακα (Normalized Matrix)
A45: Εναλλακτικές | B45: Α | C45: Β | D45: Γ | E45: Δ | F45: Ε | G45: Ζ | H45: Η | I45: Μ.Ο.
A46: A | B46: =(B35/B$42) -> 0.070248471 | C46: =(C35/C$42) -> 0.085279887 | D46: =(D35/D$42) -> 0.086691283 | E46: =(E35/E$42) -> 0.086691283 | F46: =(F35/F$42) -> 0.066666667 | G46: =(G35/G$42) -> 0.099649382 | H46: =(H35/H$42) -> 0.073339671 | I46: =AVERAGE(B46:H46) -> 0.081223806
A47: B | B47: =(B36/B$42) -> 0.046832314 | C47: =(C36/C$42) -> 0.056853258 | D47: =(D36/D$42) -> 0.057794188 | E47: =(E36/E$42) -> 0.057794188 | F47: =(F36/F$42) -> 0.066666667 | G47: =(G36/G$42) -> 0.066432921 | H47: =(H36/H$42) -> 0.048893114 | I47: =AVERAGE(B47:H47) -> 0.057323807
...

Sheet PROMETHEE
A1: Χαρακτηριστικό | B1: Τύπος | C1: q | D1: p
A2: Ενοίκιο | B2: 5 | C2: 0.1 | D2: 0.3
A3: Εμβαδό | B3: 1 | C3: - | D3: -
A4: Δωμάτια | B4: 1 | C4: - | D4: -
A5: Πάρκινγκ | B5: 2 | C5: 0.2 | D5: -
A6: Θέρμανση | B6: 1 | C6: - | D6: -
A7: Απόστ.ΜΜΜ | B7: 3 | C7: - | D7: 0.3
A8: Απόστ.Αγορά | B8: 1 | C8: - | D8: -
A9: Κατάσταση | B9: 1 | C9: - | D9: -
A10: Όροφος | B10: 1 | C10: - | D10: -
A11: Έτος | B11: 1 | C11: - | D11: -
A15: Εναλλακτική 1 | B15: Εναλλακτική 2 | C15: Ενοίκιο (Κ) | D15: Εμβαδό (Ο) | E15: Δωμάτια (Ο) | F15: Πάρκινγκ (Ο) | G15: Θέρμανση (Ο) | H15: Απόστ. ΜΜΜ (Κ) | I15: Απόστ. Αγορά (Κ) | J15: Κατάσταση (Ο) | K15: Όροφος (Ο) | L15: Έτος (Ο) | M15: π(a,b) - ROC | N15: π(a,b) - RS | O15: π(a,b) - SMART | P15: π(a,b) - AHP | Q15: π(a,b) - RR
A16: A | B16: B | C16: =IF(VLOOKUP($A16, Κανονικοποίηση!$A$2:$K$8, 2, 0) - VLOOKUP($B16, Κανονικοποίηση!$A$2:$K$8, 2, 0) <= $C$2, 0, IF(VLOOKUP($A16, Κανονικοποίηση!$A$2:$K$8, 2, 0) - VLOOKUP($B16, Κανονικοποίηση!$A$2:$K$8, 2, 0) >= $D$2, 1, (VLOOKUP($A16, Κανονικοποίηση!$A$2:$K$8, 2, 0) - VLOOKUP($B16, Κανονικοποίηση!$A$2:$K$8, 2, 0) - $C$2) / ($D$2 - $C$2))) -> 0 | D16: =IF(VLOOKUP($A16, Κανονικοποίηση!$A$2:$K$8, 3, 0) - VLOOKUP($B16, Κανονικοποίηση!$A$2:$K$8, 3, 0) > 0, 1, 0) -> 1 | E16: =IF(VLOOKUP($A16, Κανονικοποίηση!$A$2:$K$8, 4, 0) - VLOOKUP($B16, Κανονικοποίηση!$A$2:$K$8, 4, 0) > 0, 1, 0) -> 1 | F16: =IF(VLOOKUP($A16, Κανονικοποίηση!$A$2:$K$8, 5, 0) - VLOOKUP($B16, Κανονικοποίηση!$A$2:$K$8, 5, 0) > $C$5, 1, 0) -> 1 | G16: =IF(VLOOKUP($A16, Κανονικοποίηση!$A$2:$K$8, 6, 0) - VLOOKUP($B16, Κανονικοποίηση!$A$2:$K$8, 6, 0) > 0, 1, 0) -> 0 | H16: =IF(VLOOKUP($A16, Κανονικοποίηση!$A$2:$K$8, 7, 0) - VLOOKUP($B16, Κανονικοποίηση!$A$2:$K$8, 7, 0) <= 0, 0, IF(VLOOKUP($A16, Κανονικοποίηση!$A$2:$K$8, 7, 0) - VLOOKUP($B16, Κανονικοποίηση!$A$2:$K$8, 7, 0) >= $D$7, 1, (VLOOKUP($A16, Κανονικοποίηση!$A$2:$K$8, 7, 0) - VLOOKUP($B16, Κανονικοποίηση!$A$2:$K$8, 7, 0)) / $D$7)) -> 1 | I16: =IF(VLOOKUP($A16, Κανονικοποίηση!$A$2:$K$8, 8, 0) - VLOOKUP($B16, Κανονικοποίηση!$A$2:$K$8, 8, 0) > 0, 1, 0) -> 0 | J16: =IF(VLOOKUP($A16, Κανονικοποίηση!$A$2:$K$8, 9, 0) - VLOOKUP($B16, Κανονικοποίηση!$A$2:$K$8, 9, 0) > 0, 1, 0) -> 0 | K16: =IF(VLOOKUP($A16, Κανονικοποίηση!$A$2:$K$8, 10, 0) - VLOOKUP($B16, Κανονικοποίηση!$A$2:$K$8, 10, 0) > 0, 1, 0) -> 1 | L16: =IF(VLOOKUP($A16, Κανονικοποίηση!$A$2:$K$8, 11, 0) - VLOOKUP($B16, Κανονικοποίηση!$A$2:$K$8, 11, 0) > 0, 1, 0) -> 0 | M16: {=SUMPRODUCT(C16:L16, TRANSPOSE(Βάρη!$E$2:$E$11))} -> 0.5032 | N16: {=SUMPRODUCT(C16:L16, TRANSPOSE(Βάρη!$C$2:$C$11))} -> 0.54545455 | O16: {=SUMPRODUCT(C16:L16, TRANSPOSE(Βάρη!$F$2:$F$11))} -> 0.56363636 | P16: {=SUMPRODUCT(C16:L16, TRANSPOSE(Σύνοψη!$J$3:$J$12))} -> 2.3033412 | Q16: {=SUMPRODUCT(C16:L16, TRANSPOSE(Βάρη!$D$2:$D$11))} -> 0.4565777
A17: A | B17: Γ | C17: =IF(VLOOKUP($A17, Κανονικοποίηση!$A$2:$K$8, 2, 0) - VLOOKUP($B17, Κανονικοποίηση!$A$2:$K$8, 2, 0) <= $C$2, 0, IF(VLOOKUP($A17, Κανονικοποίηση!$A$2:$K$8, 2, 0) - VLOOKUP($B17, Κανονικοποίηση!$A$2:$K$8, 2, 0) >= $D$2, 1, (VLOOKUP($A17, Κανονικοποίηση!$A$2:$K$8, 2, 0) - VLOOKUP($B17, Κανονικοποίηση!$A$2:$K$8, 2, 0) - $C$2) / ($D$2 - $C$2))) -> 0 | D17: =IF(VLOOKUP($A17, Κανονικοποίηση!$A$2:$K$8, 3, 0) - VLOOKUP($B17, Κανονικοποίηση!$A$2:$K$8, 3, 0) > 0, 1, 0) -> 1 | E17: =IF(VLOOKUP($A17, Κανονικοποίηση!$A$2:$K$8, 4, 0) - VLOOKUP($B17, Κανονικοποίηση!$A$2:$K$8, 4, 0) > 0, 1, 0) -> 0 | F17: =IF(VLOOKUP($A17, Κανονικοποίηση!$A$2:$K$8, 5, 0) - VLOOKUP($B17, Κανονικοποίηση!$A$2:$K$8, 5, 0) > $C$5, 1, 0) -> 1 | G17: =IF(VLOOKUP($A17, Κανονικοποίηση!$A$2:$K$8, 6, 0) - VLOOKUP($B17, Κανονικοποίηση!$A$2:$K$8, 6, 0) > 0, 1, 0) -> 0 | H17: =IF(VLOOKUP($A17, Κανονικοποίηση!$A$2:$K$8, 7, 0) - VLOOKUP($B17, Κανονικοποίηση!$A$2:$K$8, 7, 0) <= 0, 0, IF(VLOOKUP($A17, Κανονικοποίηση!$A$2:$K$8, 7, 0) - VLOOKUP($B17, Κανονικοποίηση!$A$2:$K$8, 7, 0) >= $D$7, 1, (VLOOKUP($A17, Κανονικοποίηση!$A$2:$K$8, 7, 0) - VLOOKUP($B17, Κανονικοποίηση!$A$2:$K$8, 7, 0)) / $D$7)) -> 0 | I17: =IF(VLOOKUP($A17, Κανονικοποίηση!$A$2:$K$8, 8, 0) - VLOOKUP($B17, Κανονικοποίηση!$A$2:$K$8, 8, 0) > 0, 1, 0) -> 0 | J17: =IF(VLOOKUP($A17, Κανονικοποίηση!$A$2:$K$8, 9, 0) - VLOOKUP($B17, Κανονικοποίηση!$A$2:$K$8, 9, 0) > 0, 1, 0) -> 1 | K17: =IF(VLOOKUP($A17, Κανονικοποίηση!$A$2:$K$8, 10, 0) - VLOOKUP($B17, Κανονικοποίηση!$A$2:$K$8, 10, 0) > 0, 1, 0) -> 1 | L17: =IF(VLOOKUP($A17, Κανονικοποίηση!$A$2:$K$8, 11, 0) - VLOOKUP($B17, Κανονικοποίηση!$A$2:$K$8, 11, 0) > 0, 1, 0) -> 0 | M17: {=SUMPRODUCT(C17:L17, TRANSPOSE(Βάρη!$E$2:$E$11))} -> 0.3353 | N17: {=SUMPRODUCT(C17:L17, TRANSPOSE(Βάρη!$C$2:$C$11))} -> 0.38181818 | O17: {=SUMPRODUCT(C17:L17, TRANSPOSE(Βάρη!$F$2:$F$11))} -> 0.38181818 | P17: {=SUMPRODUCT(C17:L17, TRANSPOSE(Σύνοψη!$J$3:$J$12))} -> 1.0945118 | Q17: {=SUMPRODUCT(C17:L17, TRANSPOSE(Βάρη!$D$2:$D$11))} -> 0.32570112
